Workbook

Sheet fakturasiz
A1: tenant_id | B1: name | C1: type | D1: stir | E1: pinfl | F1: tin | G1: shop | H1: Yanvar ONKM | I1: Fevral ONKM | J1: Mart ONKM | K1: Aprel ONKM | L1: May ONKM | M1: Iyun ONKM | N1: Yanvar Faktura | O1: Fevral Faktura | P1: Mart Faktura | Q1: Aprel Faktura
A2: 55 | B2: FAXRIDDINOV NIZOMIDDIN ZIYOVUDDIN O‘G‘LI | C2: YTT | E2: 52305066540026 | F2: 52305066540026 | G2: Blok A - 9-do'kon | H2: =VLOOKUP(E2,[1]Лист1!$E$4:$F$17052,2,0) -> 0 | I2: =VLOOKUP(E2,[2]Лист1!$E$4:$F$17052,2,0) -> 64233 | J2: =VLOOKUP(E2,[3]Лист1!$E$4:$F$17052,2,0) -> 16604.4 | K2: =VLOOKUP(E2,[4]Лист1!$E$4:$F$17052,2,0) -> 34677 | L2: =VLOOKUP(E2,[5]Лист1!$E$4:$F$17055,2,0) -> 170 | M2: =VLOOKUP(E2,[6]Лист1!$E$4:$F$17055,2,0) -> 0 | N2: 0 | O2: 0 | P2: 0 | Q2: 0
A3: 117 | B3: KAMILOV ABDULLO XODJIAKBAROVICH | C3: YTT | E3: 30507850290043 | F3: 30507850290043 | G3: Blok A - 18-do'kon | H3: =VLOOKUP(E3,[1]Лист1!$E$4:$F$17052,2,0) -> 0 | I3: =VLOOKUP(E3,[2]Лист1!$E$4:$F$17052,2,0) -> 0 | J3: =VLOOKUP(E3,[3]Лист1!$E$4:$F$17052,2,0) -> 0 | K3: =VLOOKUP(E3,[4]Лист1!$E$4:$F$17052,2,0) -> 0 | L3: =VLOOKUP(E3,[5]Лист1!$E$4:$F$17055,2,0) -> 610 | M3: =VLOOKUP(E3,[6]Лист1!$E$4:$F$17055,2,0) -> 7696 | N3: 0 | O3: 0 | P3: 0 | Q3: 0
A4: 101 | B4: G‘ULOMBEKOV NODIRBEK DONIYORBEK O‘G‘LI | C4: YTT | E4: 30810860600019 | F4: 30810860600019 | G4: Blok A - 16-do'kon | H4: 0 | I4: 0 | J4: 0 | K4: 0 | L4: 0 | M4: 0 | N4: 0 | O4: 0 | P4: 0 | Q4: 0
A5: 878 | B5: NARZIYEV XURSHIDBEK XASANOVICH | C5: YTT | E5: 31308810222659 | F5: 494481009 | G5: Blok A - 13-do'kon | H5: 0 | I5: 0 | J5: 0 | K5: 0 | L5: 0 | M5: 0 | N5: 0 | O5: 0 | P5: 0 | Q5: 0
A6: 30 | B6: Osiyo Volga | C6: MCHJ | D6: 300961062 | G6: Blok A - 6-do'kon | H6: 0 | I6: 0 | J6: 0 | K6: 0 | L6: 0 | M6: 0 | N6: =VLOOKUP(E6,[7]FIRMA!$K$7:$AH$547,24,0) -> #N/A | O6: =VLOOKUP(E6,[7]FIRMA!$K$7:$AL$547,28,0) -> #N/A | P6: =VLOOKUP(E6,[8]умумий!$O$3:$CL$775,76,0) -> 0 | Q6: =VLOOKUP(E6,[9]умумий!$P$4:$AR$787,29,0) -> #N/A
A7: 426 | B7: ‘Abdul Momo‘ Mchj | C7: MCHJ | D7: 305154825 | G7: Blok SM - Merkato-do'kon | H7: 0 | I7: 0 | J7: 0 | K7: 0 | L7: 0 | M7: 0 | N7: =VLOOKUP(E7,[7]FIRMA!$K$7:$AH$547,24,0) -> #N/A | O7: =VLOOKUP(E7,[7]FIRMA!$K$7:$AL$547,28,0) -> #N/A | P7: =VLOOKUP(E7,[8]умумий!$O$3:$CL$775,76,0) -> 0 | Q7: =VLOOKUP(E7,[9]умумий!$P$4:$AR$787,29,0) -> #N/A
A8: 254 | B8: ABDUKARIMOV ABDULAZIZ XASAN O‘G‘LI | C8: YTT | E8: 31412986590057 | F8: 31412986590057 | G8: Blok B - 13-do'kon | H8: =VLOOKUP(E8,[1]Лист1!$E$4:$F$17052,2,0) -> 0 | I8: =VLOOKUP(E8,[2]Лист1!$E$4:$F$17052,2,0) -> 58850 | J8: =VLOOKUP(E8,[3]Лист1!$E$4:$F$17052,2,0) -> 21916 | K8: =VLOOKUP(E8,[4]Лист1!$E$4:$F$17052,2,0) -> 50000 | L8: =VLOOKUP(E8,[5]Лист1!$E$4:$F$17055,2,0) -> 31136.2 | M8: =VLOOKUP(E8,[6]Лист1!$E$4:$F$17055,2,0) -> 30301 | N8: 0 | O8: 0 | P8: 0 | Q8: 0
A9: 111 | B9: Maestro Expo" Mchj | C9: MCHJ | D9: 312353392 | G9: Blok A - 17-do'kon | H9: 0 | I9: 0 | J9: 0 | K9: 0 | L9: 0 | M9: 0 | N9: =VLOOKUP(E9,[7]FIRMA!$K$7:$AH$547,24,0) -> #N/A | O9: =VLOOKUP(E9,[7]FIRMA!$K$7:$AL$547,28,0) -> #N/A | P9: =VLOOKUP(E9,[8]умумий!$O$3:$CL$775,76,0) -> 0 | Q9: =VLOOKUP(E9,[9]умумий!$P$4:$AR$787,29,0) -> #N/A
A10: 488 | B10: TILLASHAYXOV SAMARIDDIN MUXITDINOVICH | C10: YTT | E10: 30706876540011 | F10: 30706876540011 | G10: Blok SM - Merkato-do'kon | H10: =VLOOKUP(E10,[1]Лист1!$E$4:$F$17052,2,0) -> 69988 | I10: =VLOOKUP(E10,[2]Лист1!$E$4:$F$17052,2,0) -> 45468 | J10: =VLOOKUP(E10,[3]Лист1!$E$4:$F$17052,2,0) -> 41450 | K10: =VLOOKUP(E10,[4]Лист1!$E$4:$F$17052,2,0) -> 2650 | L10: =VLOOKUP(E10,[5]Лист1!$E$4:$F$17055,2,0) -> 11550 | M10: =VLOOKUP(E10,[6]Лист1!$E$4:$F$17055,2,0) -> 47573 | N10: 0 | O10: 0 | P10: 0 | Q10: 0
A11: 293 | B11: ADJIBEKOV JASUR FARXOD O‘G‘LI | C11: YTT | E11: 31807946520014 | F11: 552324046 | G11: Blok B - 24-do'kon | H11: =VLOOKUP(E11,[1]Лист1!$E$4:$F$17052,2,0) -> 20784 | I11: =VLOOKUP(E11,[2]Лист1!$E$4:$F$17052,2,0) -> 40674 | J11: =VLOOKUP(E11,[3]Лист1!$E$4:$F$17052,2,0) -> 0 | K11: =VLOOKUP(E11,[4]Лист1!$E$4:$F$17052,2,0) -> 0 | L11: =VLOOKUP(E11,[5]Лист1!$E$4:$F$17055,2,0) -> 0 | M11: =VLOOKUP(E11,[6]Лист1!$E$4:$F$17055,2,0) -> 0 | N11: 0 | O11: 0 | P11: 0 | Q11: 0
A12: 174 | B12: TALIPOV XOJIAKBAR ABDURAXMANOVICH | C12: YTT | E12: 32504900222517 | F12: 32504900222517 | G12: Blok A - 27-do'kon | H12: =VLOOKUP(E12,[1]Лист1!$E$4:$F$17052,2,0) -> 18422.5 | I12: =VLOOKUP(E12,[2]Лист1!$E$4:$F$17052,2,0) -> 74377 | J12: =VLOOKUP(E12,[3]Лист1!$E$4:$F$17052,2,0) -> 34351 | K12: =VLOOKUP(E12,[4]Лист1!$E$4:$F$17052,2,0) -> 44370 | L12: =VLOOKUP(E12,[5]Лист1!$E$4:$F$17055,2,0) -> 40533.5 | M12: =VLOOKUP(E12,[6]Лист1!$E$4:$F$17055,2,0) -> 48994 | N12: 0 | O12: 0 | P12: 0 | Q12: 0
A13: 630 | B13: ABDULLAYEV BAXTIYOR ALISHER O‘G‘LI | C13: YTT | E13: 30508946540015 | F13: 30508946540015 | G13: Blok A - 31-do'kon | H13: 0 | I13: 0 | J13: 0 | K13: 0 | L13: 0 | M13: 0 | N13: 0 | O13: 0 | P13: 0 | Q13: 0
A14: 600 | B14: XAMIDOV MUXAMMADJON ABDULAZIZ O‘G‘LI | C14: YTT | E14: 30906986540011 | F14: 30906986540011 | G14: Blok A - 19-do'kon | H14: =VLOOKUP(E14,[1]Лист1!$E$4:$F$17052,2,0) -> 0 | I14: =VLOOKUP(E14,[2]Лист1!$E$4:$F$17052,2,0) -> 0 | J14: =VLOOKUP(E14,[3]Лист1!$E$4:$F$17052,2,0) -> 47411.2 | K14: =VLOOKUP(E14,[4]Лист1!$E$4:$F$17052,2,0) -> 83881 | L14: =VLOOKUP(E14,[5]Лист1!$E$4:$F$17055,2,0) -> 163790 | M14: =VLOOKUP(E14,[6]Лист1!$E$4:$F$17055,2,0) -> 72927 | N14: 0 | O14: 0 | P14: 0 | Q14: 0
A15: 723 | B15: ISHNIYAZOV TIMUR KAMARIDIN | C15: YTT | E15: 31402820260024 | F15: 31402820260024 | G15: Blok B - 42-do'kon | H15: =VLOOKUP(E15,[1]Лист1!$E$4:$F$17052,2,0) -> 0 | I15: =VLOOKUP(E15,[2]Лист1!$E$4:$F$17052,2,0) -> 0 | J15: =VLOOKUP(E15,[3]Лист1!$E$4:$F$17052,2,0) -> 0 | K15: =VLOOKUP(E15,[4]Лист1!$E$4:$F$17052,2,0) -> 9710 | L15: =VLOOKUP(E15,[5]Лист1!$E$4:$F$17055,2,0) -> 8795 | M15: =VLOOKUP(E15,[6]Лист1!$E$4:$F$17055,2,0) -> 9250.1 | N15: 0 | O15: 0 | P15: 0 | Q15: 0
A16: 318 | B16: RAXMONOV JASUR SHUXRATOVICH | C16: YTT | E16: 53110006590039 | F16: 53110006590039 | G16: Blok B - 29-do'kon | H16: =VLOOKUP(E16,[1]Лист1!$E$4:$F$17052,2,0) -> 3200 | I16: =VLOOKUP(E16,[2]Лист1!$E$4:$F$17052,2,0) -> 45693 | J16: =VLOOKUP(E16,[3]Лист1!$E$4:$F$17052,2,0) -> 25567 | K16: =VLOOKUP(E16,[4]Лист1!$E$4:$F$17052,2,0) -> 2420 | L16: =VLOOKUP(E16,[5]Лист1!$E$4:$F$17055,2,0) -> 0 | M16: =VLOOKUP(E16,[6]Лист1!$E$4:$F$17055,2,0) -> 20790 | N16: 0 | O16: 0 | P16: 0 | Q16: 0
A17: 780 | B17: YUNUSOV SAID A’LOXON DILSHOD O‘G‘LI | C17: YTT | E17: 32802940230049 | F17: 32802940230049 | G17: Blok SM - Merkato-do'kon | H17: =VLOOKUP(E17,[1]Лист1!$E$4:$F$17052,2,0) -> 9950 | I17: =VLOOKUP(E17,[2]Лист1!$E$4:$F$17052,2,0) -> 12100 | J17: =VLOOKUP(E17,[3]Лист1!$E$4:$F$17052,2,0) -> 8750 | K17: =VLOOKUP(E17,[4]Лист1!$E$4:$F$17052,2,0) -> 9300 | L17: =VLOOKUP(E17,[5]Лист1!$E$4:$F$17055,2,0) -> 13400 | M17: =VLOOKUP(E17,[6]Лист1!$E$4:$F$17055,2,0) -> 9850 | N17: 0 | O17: 0 | P17: 0 | Q17: 0
A18: 909 | B18: MUXAMMEDOV TIMUR RAIMOVICH | C18: YTT | E18: 32806862900022 | F18: 32806862900022 | G18: Blok A - 28-do'kon | H18: =VLOOKUP(E18,[1]Лист1!$E$4:$F$17052,2,0) -> 0 | I18: =VLOOKUP(E18,[2]Лист1!$E$4:$F$17052,2,0) -> 0 | J18: =VLOOKUP(E18,[3]Лист1!$E$4:$F$17052,2,0) -> 0 | K18: =VLOOKUP(E18,[4]Лист1!$E$4:$F$17052,2,0) -> 0 | L18: =VLOOKUP(E18,[5]Лист1!$E$4:$F$17055,2,0) -> 20000 | M18: =VLOOKUP(E18,[6]Лист1!$E$4:$F$17055,2,0) -> 23200 | N18: 0 | O18: 0 | P18: 0 | Q18: 0
A19: 589 | B19: IBROXIMOV ASADBEK ISOQJON O‘G‘LI | C19: YTT | E19: 32408996920053 | F19: 589719443 | G19: Blok A - 15-do'kon | H19: 0 | I19: 0 | J19: 0 | K19: 0 | L19: 0 | M19: 0 | N19: 0 | O19: 0 | P19: 0 | Q19: 0
A20: 532 | B20: SAXIBAYEV SHAROF SHOKIRJONOVICH | C20: YTT | E20: 31705862180016 | F20: 31705862180016 | G20: Blok A - 1-do'kon | H20: =VLOOKUP(E20,[1]Лист1!$E$4:$F$17052,2,0) -> 0 | I20: =VLOOKUP(E20,[2]Лист1!$E$4:$F$17052,2,0) -> 0 | J20: =VLOOKUP(E20,[3]Лист1!$E$4:$F$17052,2,0) -> 0 | K20: =VLOOKUP(E20,[4]Лист1!$E$4:$F$17052,2,0) -> 3273 | L20: =VLOOKUP(E20,[5]Лист1!$E$4:$F$17055,2,0) -> 2930 | M20: =VLOOKUP(E20,[6]Лист1!$E$4:$F$17055,2,0) -> 1280 | N20: 0 | O20: 0 | P20: 0 | Q20: 0
A21: 162 | B21: MAJIDOV MOXIRJON MUMINJONOVICH | C21: YTT | E21: 52010046610076 | F21: 52010046610076 | G21: Blok A - 25-do'kon | H21: =VLOOKUP(E21,[1]Лист1!$E$4:$F$17052,2,0) -> 0 | I21: =VLOOKUP(E21,[2]Лист1!$E$4:$F$17052,2,0) -> 72615 | J21: =VLOOKUP(E21,[3]Лист1!$E$4:$F$17052,2,0) -> 62762.5 | K21: =VLOOKUP(E21,[4]Лист1!$E$4:$F$17052,2,0) -> 80299.5 | L21: =VLOOKUP(E21,[5]Лист1!$E$4:$F$17055,2,0) -> 45691 | M21: =VLOOKUP(E21,[6]Лист1!$E$4:$F$17055,2,0) -> 85989 | N21: 0 | O21: 0 | P21: 0 | Q21: 0
A22: 775 | B22: MUXAMMADIYEV JASUR ABDUJAMILEVICH | C22: YTT | E22: 32508892560062 | F22: 603556809 | G22: Blok SM - Merkato-do'kon | H22: =VLOOKUP(E22,[1]Лист1!$E$4:$F$17052,2,0) -> 0 | I22: =VLOOKUP(E22,[2]Лист1!$E$4:$F$17052,2,0) -> 0 | J22: =VLOOKUP(E22,[3]Лист1!$E$4:$F$17052,2,0) -> 0 | K22: =VLOOKUP(E22,[4]Лист1!$E$4:$F$17052,2,0) -> 4777 | L22: =VLOOKUP(E22,[5]Лист1!$E$4:$F$17055,2,0) -> 31555 | M22: =VLOOKUP(E22,[6]Лист1!$E$4:$F$17055,2,0) -> 12315 | N22: 0 | O22: 0 | P22: 0 | Q22: 0
A23: 914 | B23: UMARBEKOV JOVLONBEK RAVSHANBEKOVICH | C23: YTT | E23: 30711820220099 | F23: 30711820220099 | G23: Blok A - 28-do'kon | H23: 0 | I23: 0 | J23: 0 | K23: 0 | L23: 0 | M23: 0 | N23: 0 | O23: 0 | P23: 0 | Q23: 0
A24: 691 | B24: SHAIKRAMOV ULUGBEK RUSTAMOVICH | C24: YTT | E24: 30902870170034 | F24: 30902870170034 | G24: Blok B - 2-do'kon | H24: 0 | I24: 0 | J24: 0 | K24: 0 | L24: 0 | M24: 0 | N24: 0 | O24: 0 | P24: 0 | Q24: 0
A25: 275 | B25: ABDUKARIMOV ABDULAZIZ XASAN O‘G‘LI | C25: YTT | E25: 31412986590057 | F25: 31412986590057 | G25: Blok B - 18-do'kon | H25: =VLOOKUP(E25,[1]Лист1!$E$4:$F$17052,2,0) -> 0 | I25: =VLOOKUP(E25,[2]Лист1!$E$4:$F$17052,2,0) -> 58850 | J25: =VLOOKUP(E25,[3]Лист1!$E$4:$F$17052,2,0) -> 21916 | K25: =VLOOKUP(E25,[4]Лист1!$E$4:$F$17052,2,0) -> 50000 | L25: =VLOOKUP(E25,[5]Лист1!$E$4:$F$17055,2,0) -> 31136.2 | M25: =VLOOKUP(E25,[6]Лист1!$E$4:$F$17055,2,0) -> 30301 | N25: 0 | O25: 0 | P25: 0 | Q25: 0
A26: 323 | B26: MIRZAXIDOV ABDULXAY ADXAMOVICH | C26: YTT | E26: 31402710170053 | F26: 31402710170053 | G26: Blok B - 29-do'kon | H26: =VLOOKUP(E26,[1]Лист1!$E$4:$F$17052,2,0) -> 2000 | I26: =VLOOKUP(E26,[2]Лист1!$E$4:$F$17052,2,0) -> 73139 | J26: =VLOOKUP(E26,[3]Лист1!$E$4:$F$17052,2,0) -> 13470 | K26: =VLOOKUP(E26,[4]Лист1!$E$4:$F$17052,2,0) -> 9564 | L26: =VLOOKUP(E26,[5]Лист1!$E$4:$F$17055,2,0) -> 7000 | M26: =VLOOKUP(E26,[6]Лист1!$E$4:$F$17055,2,0) -> 15540 | N26: 0 | O26: 0 | P26: 0 | Q26: 0
A27: 320 | B27: TOLIPOV OQILJON ABDURASULOVICH | C27: YTT | E27: 52703066610017 | F27: 52703066610017 | G27: Blok B - 29-do'kon | H27: =VLOOKUP(E27,[1]Лист1!$E$4:$F$17052,2,0) -> 18850 | I27: =VLOOKUP(E27,[2]Лист1!$E$4:$F$17052,2,0) -> 44304.5 | J27: =VLOOKUP(E27,[3]Лист1!$E$4:$F$17052,2,0) -> 24269 | K27: =VLOOKUP(E27,[4]Лист1!$E$4:$F$17052,2,0) -> 20700 | L27: =VLOOKUP(E27,[5]Лист1!$E$4:$F$17055,2,0) -> 56090 | M27: =VLOOKUP(E27,[6]Лист1!$E$4:$F$17055,2,0) -> 29628 | N27: 0 | O27: 0 | P27: 0 | Q27: 0
A28: 114 | B28: HOTAMOV NAJMIDDINBEK O‘KTAM O‘G‘LI | C28: YTT | E28: 51201006500020 | F28: 51201006500020 | G28: Blok A - 18-do'kon | H28: 0 | I28: 0 | J28: 0 | K28: 0 | L28: 0 | M28: 0 | N28: 0 | O28: 0 | P28: 0 | Q28: 0
A29: 85 | B29: RAIMOV ABDUGANI ABDUJALILOVICH | C29: YTT | E29: 31407866520013 | F29: 31407866520013 | G29: Blok A - 13-do'kon | H29: =VLOOKUP(E29,[1]Лист1!$E$4:$F$17052,2,0) -> 45229 | I29: =VLOOKUP(E29,[2]Лист1!$E$4:$F$17052,2,0) -> 86321 | J29: =VLOOKUP(E29,[3]Лист1!$E$4:$F$17052,2,0) -> 0 | K29: =VLOOKUP(E29,[4]Лист1!$E$4:$F$17052,2,0) -> 0 | L29: =VLOOKUP(E29,[5]Лист1!$E$4:$F$17055,2,0) -> 0 | M29: =VLOOKUP(E29,[6]Лист1!$E$4:$F$17055,2,0) -> 0 | N29: 0 | O29: 0 | P29: 0 | Q29: 0
A30: 70 | B30: XAKIMJONOV JAFARALI RASULJON O‘G‘LI | C30: YTT | E30: 52709026610017 | F30: 634565780 | G30: Blok A - 12-do'kon | H30: =VLOOKUP(E30,[1]Лист1!$E$4:$F$17052,2,0) -> 0 | I30: =VLOOKUP(E30,[2]Лист1!$E$4:$F$17052,2,0) -> 10840 | J30: =VLOOKUP(E30,[3]Лист1!$E$4:$F$17052,2,0) -> 4639 | K30: =VLOOKUP(E30,[4]Лист1!$E$4:$F$17052,2,0) -> 9035 | L30: =VLOOKUP(E30,[5]Лист1!$E$4:$F$17055,2,0) -> 19897 | M30: =VLOOKUP(E30,[6]Лист1!$E$4:$F$17055,2,0) -> 7009 | N30: 0 | O30: 0 | P30: 0 | Q30: 0
A31: 124 | B31: GAZIZYANOV SHAMIL SALAVATOVICH | C31: YTT | E31: 31810800140020 | F31: 499864634 | G31: Blok A - 19-do'kon | H31: =VLOOKUP(E31,[1]Лист1!$E$4:$F$17052,2,0) -> 0 | I31: =VLOOKUP(E31,[2]Лист1!$E$4:$F$17052,2,0) -> 25155 | J31: =VLOOKUP(E31,[3]Лист1!$E$4:$F$17052,2,0) -> 70520 | K31: =VLOOKUP(E31,[4]Лист1!$E$4:$F$17052,2,0) -> 44924.6 | L31: =VLOOKUP(E31,[5]Лист1!$E$4:$F$17055,2,0) -> 73260 | M31: =VLOOKUP(E31,[6]Лист1!$E$4:$F$17055,2,0) -> 36190 | N31: 0 | O31: 0 | P31: 0 | Q31: 0
A32: 24 | B32: ERGASHEV KOMILJON RUSTAM O‘G‘LI | C32: YTT | E32: 31511996570010 | F32: 567867422 | G32: Blok A - 5-do'kon | H32: =VLOOKUP(E32,[1]Лист1!$E$4:$F$17052,2,0) -> 0 | I32: =VLOOKUP(E32,[2]Лист1!$E$4:$F$17052,2,0) -> 15942 | J32: =VLOOKUP(E32,[3]Лист1!$E$4:$F$17052,2,0) -> 30500 | K32: =VLOOKUP(E32,[4]Лист1!$E$4:$F$17052,2,0) -> 32681 | L32: =VLOOKUP(E32,[5]Лист1!$E$4:$F$17055,2,0) -> 24545 | M32: =VLOOKUP(E32,[6]Лист1!$E$4:$F$17055,2,0) -> 22455 | N32: 0 | O32: 0 | P32: 0 | Q32: 0
A33: 544 | B33: IBROHIMOV JO‘RABEK AHMADJON O‘G‘LI | C33: YTT | E33: 32109986540032 | F33: 32109986540032 | G33: Blok A - 4-do'kon | H33: =VLOOKUP(E33,[1]Лист1!$E$4:$F$17052,2,0) -> 51863.8 | I33: =VLOOKUP(E33,[2]Лист1!$E$4:$F$17052,2,0) -> 38250 | J33: =VLOOKUP(E33,[3]Лист1!$E$4:$F$17052,2,0) -> 39190 | K33: =VLOOKUP(E33,[4]Лист1!$E$4:$F$17052,2,0) -> 81933.5 | L33: =VLOOKUP(E33,[5]Лист1!$E$4:$F$17055,2,0) -> 70233.4 | M33: =VLOOKUP(E33,[6]Лист1!$E$4:$F$17055,2,0) -> 31644 | N33: 0 | O33: 0 | P33: 0 | Q33: 0
A34: 12 | B34: Intouch" Mchj | C34: MCHJ | D34: 306067924 | G34: Blok A - 3-do'kon | H34: 0 | I34: 0 | J34: 0 | K34: 0 | L34: 0 | M34: 0 | N34: =VLOOKUP(E34,[7]FIRMA!$K$7:$AH$547,24,0) -> #N/A | O34: =VLOOKUP(E34,[7]FIRMA!$K$7:$AL$547,28,0) -> #N/A | P34: =VLOOKUP(E34,[8]умумий!$O$3:$CL$775,76,0) -> 0 | Q34: =VLOOKUP(E34,[9]умумий!$P$4:$AR$787,29,0) -> #N/A
A35: 35 | B35: BERDIYEV SHAXZOD ZOKIR O‘G‘LI | C35: YTT | E35: 31412936600012 | F35: 504482262 | G35: Blok A - 7-do'kon | H35: 0 | I35: 0 | J35: 0 | K35: 0 | L35: 0 | M35: 0 | N35: 0 | O35: 0 | P35: 0 | Q35: 0
A36: 17 | B36: RASULOV MAXMUDJON DEXKANBAYEVICH | C36: YTT | E36: 30303720221421 | F36: 456122163 | G36: Blok A - 4-do'kon | H36: =VLOOKUP(E36,[1]Лист1!$E$4:$F$17052,2,0) -> 0 | I36: =VLOOKUP(E36,[2]Лист1!$E$4:$F$17052,2,0) -> 2240 | J36: =VLOOKUP(E36,[3]Лист1!$E$4:$F$17052,2,0) -> 7320 | K36: =VLOOKUP(E36,[4]Лист1!$E$4:$F$17052,2,0) -> 18694.8 | L36: =VLOOKUP(E36,[5]Лист1!$E$4:$F$17055,2,0) -> 16658 | M36: =VLOOKUP(E36,[6]Лист1!$E$4:$F$17055,2,0) -> 3420 | N36: 0 | O36: 0 | P36: 0 | Q36: 0
A37: 879 | B37: TUROBOV ABDULSHUKUR ABDUQAYUM O‘G‘LI | C37: YTT | E37: 31505950210045 | F37: 31505950210045 | G37: Blok A - 13-do'kon | H37: 0 | I37: 0 | J37: 0 | K37: 0 | L37: 0 | M37: 0 | N37: 0 | O37: 0 | P37: 0 | Q37: 0
A38: 269 | B38: ALIYOROVA NATALIYA KUSHMURATOVNA | C38: YTT | E38: 42206810230088 | F38: 486931320 | G38: Blok B - 16-do'kon | H38: =VLOOKUP(E38,[1]Лист1!$E$4:$F$17052,2,0) -> 0 | I38: =VLOOKUP(E38,[2]Лист1!$E$4:$F$17052,2,0) -> 0 | J38: =VLOOKUP(E38,[3]Лист1!$E$4:$F$17052,2,0) -> 850 | K38: =VLOOKUP(E38,[4]Лист1!$E$4:$F$17052,2,0) -> 14180 | L38: =VLOOKUP(E38,[5]Лист1!$E$4:$F$17055,2,0) -> 12500 | M38: =VLOOKUP(E38,[6]Лист1!$E$4:$F$17055,2,0) -> 13060 | N38: 0 | O38: 0 | P38: 0 | Q38: 0
A39: 665 | B39: MURADJANOV JAVOHIR ALIMDJON O‘G‘LI | C39: YTT | E39: 52611076590040 | F39: 52611076590040 | G39: Blok A - 18-do'kon | H39: =VLOOKUP(E39,[1]Лист1!$E$4:$F$17052,2,0) -> 0 | I39: =VLOOKUP(E39,[2]Лист1!$E$4:$F$17052,2,0) -> 0 | J39: =VLOOKUP(E39,[3]Лист1!$E$4:$F$17052,2,0) -> 0 | K39: =VLOOKUP(E39,[4]Лист1!$E$4:$F$17052,2,0) -> 0 | L39: =VLOOKUP(E39,[5]Лист1!$E$4:$F$17055,2,0) -> 0 | M39: =VLOOKUP(E39,[6]Лист1!$E$4:$F$17055,2,0) -> 125403.1 | N39: 0 | O39: 0 | P39: 0 | Q39: 0
A40: 606 | B40: NIYAZOV SHERZOD AXMADALIYEVICH | C40: YTT | E40: 32401910241399 | F40: 32401910241399 | G40: Blok A - 19-do'kon | H40: =VLOOKUP(E40,[1]Лист1!$E$4:$F$17052,2,0) -> 0 | I40: =VLOOKUP(E40,[2]Лист1!$E$4:$F$17052,2,0) -> 0 | J40: =VLOOKUP(E40,[3]Лист1!$E$4:$F$17052,2,0) -> 0 | K40: =VLOOKUP(E40,[4]Лист1!$E$4:$F$17052,2,0) -> 4770 | L40: =VLOOKUP(E40,[5]Лист1!$E$4:$F$17055,2,0) -> 24467.5 | M40: =VLOOKUP(E40,[6]Лист1!$E$4:$F$17055,2,0) -> 10055 | N40: 0 | O40: 0 | P40: 0 | Q40: 0
...
