Workbook

Sheet умумий
A2: T/R | B2: Blok | C2: Do'kon raqami | D2: Kadastr raqami | E2: Do'kon egasi F.I.Sh | F2: JSHSHIR raqami | G2: Telefon raqami | H2: Do'kon egasiga tegishli MCHJ nomi | I2: Do'kon umumiy maydoni | J2: ijaraga olgan tadbirkor soni | K2: Ijaraga berilgan maydoni kv.m | L2: Faoliyat olib borayotgan Tadbirkorlik subyektining nomi | M2: Faoliyat olib borayotgan Tadbirkorlik subyekti Rahbarining JSHSHIR raqami | N2: Faoliyat olib borayotgan Tadbirkorlik subyekti Rahbarining F.I.SH | O2: Faoliyat olib borayotgan Tadbirkorlik subyekti Rahbarining Telefon raqami | P2: Faoliyat olib borayotgan yakka tartibdagi tadbirkorning (YTT) JSHSHIR raqami | Q2: Faoliyat olib borayotgan Yuridik shaxsning (MCHJ) STIR raqami | R2: Faoliyat olib borayotgan Tadbirkorlik subyektida ishlaydigan xodimlar soni | S2: Faoliyat olib borayotgan Tadbirkorlik subyektida ishlaydigan xodimlar, F.I.SH raqami | T2: Faoliyat olib borayotgan Tadbirkorlik subyektida ishlaydigan xodimlar, JSHSHIR raqami | U2: Faoliyat olib borayotgan Tadbirkorlik subyektida ishlaydigan xodimlar, Telefon raqami | V2: Tadbirkorlik turi | W2: Soliq turi (QQS, Aylanmadan olinadigan soliq) | X2: Kassa apparat raqami | Y2: Savdo do'koniga 1 oy davomida kirayotgan fuqarolar soni (Videokuzatuv orqali) | Z2: Savdo do'koniga 1 kun davomida kirayotgan fuqarolar soni (Videokuzatuv orqali) | AA2: Tadbirkorlik Subyekti holati (FAOL/NOFAOL) | AB2: Yong'in xavfsizlik darajasi | AC2: Yong'indan xabar beruvchi qurilma | AD2: Birlamchi yong'in o'chirish vositasi (Ognetushitel) turi,soni | AE2: Qizil toifaga kirgan do'kon (Qizilga kirgan Sababi) | AF2: ONKM Йил бошидан | AH2: Ой бошидан | AJ2: Кунлик | AL2: Elektron to'lovlar Йил бошидан | AN2: Elektron to'lovlar Oy бошидан
AF3: ОНКМ суммаси | AG3: Чек сони | AH3: ОНКМ суммаси | AI3: Чек сони | AJ3: ОНКМ суммаси | AK3: Чек сони | AL3: soni | AM3: summasi | AN3: soni | AO3: summasi
A4: 1 | B4: Blok A | C4: 1-do'kon | D4: 10:10:40:01:01:0011/0012 | E4: Alimov Ulugbek Rustamovich | F4: 30809640040022 | G4: 951773373 | H4: PREMIUM PRIME SERVICE" MAS`ULIYATI CHEKLANGAN JAMIYATI | I4: 180 | J4: 1 | K4: 40 | L4: "NETTRA" MCHJ | M4: 52709046530021 | N4: YOQUBOV SUNNATILLA NODIR O‘G‘LI | O4: 333173003 | Q4: 312658448 | R4: 1 | S4: YOQUBOV SUNNATILLA NODIR O‘G‘LI | T4: 52709046530021 | U4: 312658448 | V4: Yuridik | W4: QQS | X4: LG420211628643 | AA4: Faol | AF4: 2230.9 | AG4: 461 | AH4: 159.7 | AI4: 36 | AJ4: 16 | AK4: 3 | AL4: 16 | AM4: 10033.145 | AN4: 0 | AO4: =+VLOOKUP(Q4,[1]умумий!$P$4:$EB$787,117,0) -> 0
A5: 2 | B5: Blok A | C5: 1-do'kon | D5: 10:10:40:01:01:0011/0012 | E5: Alimov Ulugbek Rustamovich | F5: 30809640040022 | G5: 951773373 | H5: PREMIUM PRIME SERVICE" MAS`ULIYATI CHEKLANGAN JAMIYATI | I5: 0 | J5: 1 | K5: 40 | L5: Xakimov Botir Baxtiyarovich | M5: 30105830210098 | N5: Xakimov Botir Baxtiyarovich | O5: 977751515 | P5: 30105830210098 | R5: 5 | S5: МАРАСИЛОВ ОЙБЕК УСМАНОВИЧ | T5: 31705862180016 50204056590048 50307006610055 32801901951122 32005985970048 | U5: 936688000 000000000 000000000 940057111 940527799 | V5: YTT | W5: QQS | X5: VG300750002569 | AA5: Faol | AF5: 448.8 | AG5: 269 | AH5: 45.1 | AI5: 65 | AJ5: 3.8 | AK5: 2 | AL5: 0 | AM5: 0 | AN5: 0 | AO5: =+VLOOKUP(Q5,[1]умумий!$P$4:$EB$787,117,0) -> #N/A
A6: 3 | B6: Blok A | C6: 1-do'kon | D6: 10:10:40:01:01:0011/0012 | E6: Alimov Ulugbek Rustamovich | F6: 30809640040022 | G6: 951773373 | H6: PREMIUM PRIME SERVICE" MAS`ULIYATI CHEKLANGAN JAMIYATI | I6: 0 | J6: 1 | K6: 40 | L6: Islombekov Otabek Rustambek O'g'li | M6: 30208940330022 | N6: Islombekov Otabek Rustambek O'g'li | O6: +998946447750 | P6: 30208940330022 | R6: 5 | S6: ISMANOV MAXMUDJON MUROD O‘G‘LI | T6: 32608950260036 50201048660055 31212840220049 51303046730028 50202006590023 | U6: 947945599 000000000 000000000 935541343 957876996 | V6: YTT | W6: AOS | X6: LG420211621180 | AA6: Faol | AF6: 229.3 | AG6: 296 | AH6: 60.6 | AI6: 97 | AJ6: 2.7 | AK6: 2 | AL6: 12 | AM6: 15.93 | AN6: 0 | AO6: =+VLOOKUP(Q6,[1]умумий!$P$4:$EB$787,117,0) -> #N/A
A7: 4 | B7: Blok A | C7: 1-do'kon | D7: 10:10:40:01:01:0011/0012 | E7: Alimov Ulugbek Rustamovich | F7: 30809640040022 | G7: 951773373 | H7: PREMIUM PRIME SERVICE" MAS`ULIYATI CHEKLANGAN JAMIYATI | I7: 0 | J7: 1 | K7: 40 | L7: МАРАСИЛОВ ОЙБЕК УСМАНОВИЧ | M7: 32909770170047 | N7: МАРАСИЛОВ ОЙБЕК УСМАНОВИЧ | O7: 999937216 | P7: 32909770170047 | R7: 1 | S7: МАРАСИЛОВ ОЙБЕК УСМАНОВИЧ | T7: 32909770170047 | U7: 999937216 | V7: YTT | W7: AOS | X7: UZ201125124416 | AA7: Faol | AF7: 150.3 | AG7: 49 | AH7: 31.5 | AI7: 11 | AJ7: 0.8 | AK7: 1 | AL7: 0 | AM7: 0 | AN7: 0 | AO7: =+VLOOKUP(Q7,[1]умумий!$P$4:$EB$787,117,0) -> #N/A
A8: 5 | B8: Blok A | C8: 1-do'kon | D8: 10:10:40:01:01:0011/0012 | E8: Alimov Ulugbek Rustamovich | F8: 30809640040022 | G8: 951773373 | H8: PREMIUM PRIME SERVICE" MAS`ULIYATI CHEKLANGAN JAMIYATI | I8: 0 | J8: 1 | K8: 20 | L8: ISMANOV MAXMUDJON MUROD O‘G‘LI | M8: 50608006610020 | N8: ISMANOV MAXMUDJON MUROD O‘G‘LI | O8: 941115544 | P8: 50608006610020 | R8: 1 | S8: ISMANOV MAXMUDJON MUROD O‘G‘LI | T8: 50608006610020 | U8: 941115544 | V8: YTT | W8: AOS | X8: LG420211621377 | AA8: Faol | AF8: 87.1 | AG8: 41 | AH8: 4.6 | AI8: 16 | AJ8: 0 | AK8: 0 | AL8: 2 | AM8: 4.4 | AN8: 0 | AO8: =+VLOOKUP(Q8,[1]умумий!$P$4:$EB$787,117,0) -> #N/A
A9: 6 | B9: Blok A | C9: 2-do'kon | D9: 10:10:01:01:01:0024 | E9: AbdumalikovAkmal Pulat o'g'li | F9: 51010066600018 | G9: 935272727 | H9: PREMIUM PRIME SERVICE" MAS`ULIYATI CHEKLANGAN JAMIYATI | I9: 180 | J9: 1 | K9: 15 | L9: FIRDAVS-ZOHID SAVDO | M9: 43011920330011 | N9: USMONOVA MUQADDAS SHUXRATJONOVNA | O9: 958598008 | Q9: 301758598 | R9: 1 | S9: USMONOVA MUQADDAS SHUXRATJONOVNA | T9: 43011920330011 | U9: 958598008 | V9: Yuridik | W9: QQS | X9: LG420211601706 | AA9: Faol | AF9: 643.2 | AG9: 164 | AH9: 49.2 | AI9: 14 | AJ9: 18 | AK9: 3 | AL9: 43 | AM9: 10387.767 | AN9: 0 | AO9: =+VLOOKUP(Q9,[1]умумий!$P$4:$EB$787,117,0) -> 0
A10: 735 | B10: Blok A | C10: 2-do'kon | D10: 10:10:01:01:01:0024 | E10: AbdumalikovAkmal Pulat o'g'li | F10: 51010066600018 | G10: 935272727 | H10: PREMIUM PRIME SERVICE" MAS`ULIYATI CHEKLANGAN JAMIYATI | I10: 0 | J10: 1 | K10: 15 | L10: JO‘RAQOBILOV SIROJIDDIN O‘ROL O‘G‘LI | M10: 52104006840053 | N10: JO‘RAQOBILOV SIROJIDDIN O‘ROL O‘G‘LI | P10: 52104006840053 | R10: 1 | S10: JO‘RAQOBILOV SIROJIDDIN O‘ROL O‘G‘LI | T10: 52104006840053 | V10: YTT | W10: AOS | X10: LG420211635350 | AF10: 98.7 | AG10: 88 | AH10: 10.8 | AI10: 14 | AJ10: 0 | AK10: 0 | AL10: 0 | AM10: 0 | AN10: 0 | AO10: =+VLOOKUP(Q10,[1]умумий!$P$4:$EB$787,117,0) -> #N/A
A11: 7 | B11: Blok A | C11: 2-do'kon | D11: 10:10:01:01:01:0024 | E11: AbdumalikovAkmal Pulat o'g'li | F11: 51010066600018 | G11: 935272727 | H11: PREMIUM PRIME SERVICE" MAS`ULIYATI CHEKLANGAN JAMIYATI | I11: 0 | J11: 1 | K11: 15 | L11: USMANOV UKTAMJON XAMIDOVICH | M11: 30405602100034 | N11: USMANOV UKTAMJON XAMIDOVICH | O11: 955535040 | P11: 30405602100034 | R11: 1 | S11: USMANOV UKTAMJON XAMIDOVICH | T11: 30405602100034 | U11: 955535040 | V11: YTT | W11: AOS | X11: VG544170040421 | AA11: Faol | AF11: 0 | AG11: 1 | AH11: 0 | AI11: 0 | AJ11: 0 | AK11: 0 | AL11: 0 | AM11: 0 | AN11: 0 | AO11: =+VLOOKUP(Q11,[1]умумий!$P$4:$EB$787,117,0) -> #N/A
A12: 8 | B12: Blok A | C12: 2-do'kon | D12: 10:10:01:01:01:0024 | E12: AbdumalikovAkmal Pulat o'g'li | F12: 51010066600018 | G12: 935272727 | H12: PREMIUM PRIME SERVICE" MAS`ULIYATI CHEKLANGAN JAMIYATI | I12: 0 | J12: 1 | K12: 15 | L12: SALIYEV ULUG‘BEK BAXTIYOR O‘G‘LI | M12: 30601910171605 | N12: SALIYEV ULUG‘BEK BAXTIYOR O‘G‘LI | O12: 951107577 | P12: 30601910171605 | R12: 1 | S12: SALIYEV ULUG‘BEK BAXTIYOR O‘G‘LI | T12: 30601910171605 | U12: 951107577 | V12: YTT | W12: AOS | X12: 0 | AA12: Faol | AF12: 0 | AG12: 0 | AH12: 0 | AI12: 0 | AJ12: 0 | AK12: 0 | AL12: 0 | AM12: 0 | AN12: 0 | AO12: =+VLOOKUP(Q12,[1]умумий!$P$4:$EB$787,117,0) -> #N/A
A13: 9 | B13: Blok A | C13: 2-do'kon | D13: 10:10:01:01:01:0024 | E13: AbdumalikovAkmal Pulat o'g'li | F13: 51010066600018 | G13: 935272727 | H13: PREMIUM PRIME SERVICE" MAS`ULIYATI CHEKLANGAN JAMIYATI | I13: 0 | J13: 1 | K13: 15 | L13: BERDIYOROV ASROR SHUHRAT O‘G‘LI | M13: 31208966580017 | N13: BERDIYOROV ASROR SHUHRAT O‘G‘LI | O13: 935475515 | P13: 31208966580017 | R13: 1 | S13: BERDIYOROV ASROR SHUHRAT O‘G‘LI | T13: 31208966580017 | U13: 935475515 | V13: YTT | W13: AOS | X13: LG420211610963 | AA13: Faol | AF13: 129.7 | AG13: 99 | AH13: 27.6 | AI13: 20 | AJ13: 0 | AK13: 0 | AL13: 0 | AM13: 0 | AN13: 0 | AO13: =+VLOOKUP(Q13,[1]умумий!$P$4:$EB$787,117,0) -> #N/A
A14: 10 | B14: Blok A | C14: 2-do'kon | D14: 10:10:01:01:01:0024 | E14: AbdumalikovAkmal Pulat o'g'li | F14: 51010066600018 | G14: 935272727 | H14: PREMIUM PRIME SERVICE" MAS`ULIYATI CHEKLANGAN JAMIYATI | I14: 0 | J14: 1 | K14: 15 | L14: Abduraimov Mamurjon Abduxamidovich | M14: 32005810020025 | N14: Abduraimov Mamurjon Abduxamidovich | O14: 981211900 | P14: 32005810020025 | R14: 4 | S14: ANVAROV OYBEK A’ZAMJON O‘G‘LI KOMILJONOV KAMRONBEK SANJARBEK O‘G‘LI XAYRIDDINOV ABDULLOH ZUHRIDDIN O'G'LI TOIRXONOV IBROHIMXON FATTOXXON O‘G‘LI | T14: 30708942190047 52310066750034 51605048680034 50906016750023 | U14: 998981211900 998981211900 998900000000 998974636446 | V14: YTT | W14: AOS | X14: LG420211629211 | AA14: Faol | AF14: 220.4 | AG14: 191 | AH14: 68.2 | AI14: 49 | AJ14: 1.5 | AK14: 5 | AL14: 0 | AM14: 0 | AN14: 0 | AO14: =+VLOOKUP(Q14,[1]умумий!$P$4:$EB$787,117,0) -> #N/A
A15: 11 | B15: Blok A | C15: 2-do'kon | D15: 10:10:01:01:01:0024 | E15: AbdumalikovAkmal Pulat o'g'li | F15: 51010066600018 | G15: 935272727 | H15: PREMIUM PRIME SERVICE" MAS`ULIYATI CHEKLANGAN JAMIYATI | I15: 0 | J15: 1 | K15: 15 | L15: AXMADJON TALIPOV ABDUXAMIDOVICH | M15: 32704700220023 | N15: AXMADJON TALIPOV ABDUXAMIDOVICH | O15: 977705250 | P15: 32704700220023 | R15: 1 | S15: AXMADJON TALIPOV ABDUXAMIDOVICH | T15: 32704700220023 | U15: 977705250 | V15: YTT | W15: AOS | X15: NA000000028602 | AA15: Faol | AF15: 128.2 | AG15: 98 | AH15: 4.9 | AI15: 13 | AJ15: 0.1 | AK15: 1 | AL15: 4 | AM15: 14.9 | AN15: 0 | AO15: =+VLOOKUP(Q15,[1]умумий!$P$4:$EB$787,117,0) -> #N/A
A16: 12 | B16: Blok A | C16: 2-do'kon | D16: 10:10:01:01:01:0024 | E16: AbdumalikovAkmal Pulat o'g'li | F16: 51010066600018 | G16: 935272727 | H16: PREMIUM PRIME SERVICE" MAS`ULIYATI CHEKLANGAN JAMIYATI | I16: 0 | J16: 1 | K16: 15 | L16: ISMOILOV ABDULAZIZ RAHMONJON O‘G‘LI | M16: 32709966530013 | N16: ISMOILOV ABDULAZIZ RAHMONJON O‘G‘LI | O16: 977488267 | P16: 32709966530013 | R16: 1 | S16: ISMOILOV ABDULAZIZ RAHMONJON O‘G‘LI | T16: 32709966530013 | U16: 977488267 | V16: YTT | W16: AOS | X16: VG496170003200 | AA16: Faol | AF16: 39.6 | AG16: 28 | AH16: 39.5 | AI16: 24 | AJ16: 0 | AK16: 0 | AL16: 16 | AM16: 29.56 | AN16: 2 | AO16: =+VLOOKUP(Q16,[1]умумий!$P$4:$EB$787,117,0) -> #N/A
A17: 13 | B17: Blok A | C17: 2-do'kon | D17: 10:10:01:01:01:0024 | E17: AbdumalikovAkmal Pulat o'g'li | F17: 51010066600018 | G17: 935272727 | H17: PREMIUM PRIME SERVICE" MAS`ULIYATI CHEKLANGAN JAMIYATI | I17: 0 | J17: 1 | K17: 15 | L17: XUSANJON UCHKUNOV UTKUR O‘G‘LI | M17: 50205006610041 | N17: XUSANJON UCHKUNOV UTKUR O‘G‘LI | O17: 946673088 | P17: 50205006610041 | R17: 1 | S17: XUSANJON UCHKUNOV UTKUR O‘G‘LI | T17: 50205006610041 | U17: 946673088 | V17: YTT | W17: AOS | X17: LG420211621163 | AA17: Faol | AF17: 64.1 | AG17: 166 | AH17: 11 | AI17: 47 | AJ17: 0 | AK17: 0 | AL17: 11 | AM17: 14.94 | AN17: 1 | AO17: =+VLOOKUP(Q17,[1]умумий!$P$4:$EB$787,117,0) -> #N/A
A18: 14 | B18: Blok A | C18: 2-do'kon | D18: 10:10:01:01:01:0024 | E18: AbdumalikovAkmal Pulat o'g'li | F18: 51010066600018 | G18: 935272727 | H18: PREMIUM PRIME SERVICE" MAS`ULIYATI CHEKLANGAN JAMIYATI | I18: 0 | J18: 1 | K18: 15 | L18: SA’DULLAYEV HOTAMJON SHAVKATJON O‘G‘LI | M18: 50602016500014 | N18: SA’DULLAYEV HOTAMJON SHAVKATJON O‘G‘LI | O18: 990370761 | P18: 50602016500014 | R18: 1 | S18: SA’DULLAYEV HOTAMJON SHAVKATJON O‘G‘LI | T18: 50602016500014 | U18: 990370761 | V18: YTT | W18: AOS | X18: LG420211609130 | AA18: Faol | AF18: 68.5 | AG18: 76 | AH18: 6.1 | AI18: 14 | AJ18: 0.3 | AK18: 1 | AL18: 2 | AM18: 12.29 | AN18: 0 | AO18: =+VLOOKUP(Q18,[1]умумий!$P$4:$EB$787,117,0) -> #N/A
A19: 15 | B19: Blok A | C19: 2-do'kon | D19: 10:10:01:01:01:0024 | E19: AbdumalikovAkmal Pulat o'g'li | F19: 51010066600018 | G19: 935272727 | H19: PREMIUM PRIME SERVICE" MAS`ULIYATI CHEKLANGAN JAMIYATI | I19: 0 | J19: 1 | K19: 15 | L19: Voxidov Abdulloh Qodirjon O'g'li | M19: 52403006540012 | N19: Voxidov Abdulloh Qodirjon O'g'li | O19: +998971711001 | P19: 52403006540012 | R19: 1 | S19: BAXTIYOROV DILMUROD ELDIYOR O‘G‘LI | T19: 52810016500020 | U19: 998971711001 | V19: YTT | W19: AOS | X19: LG420211629139 | AA19: Faol | AF19: 105.3 | AG19: 192 | AH19: 23.5 | AI19: 27 | AJ19: 0 | AK19: 0 | AL19: 0 | AM19: 0 | AN19: 0 | AO19: =+VLOOKUP(Q19,[1]умумий!$P$4:$EB$787,117,0) -> #N/A
A20: 16 | B20: Blok A | C20: 2-do'kon | D20: 10:10:01:01:01:0024 | E20: AbdumalikovAkmal Pulat o'g'li | F20: 51010066600018 | G20: 935272727 | H20: PREMIUM PRIME SERVICE" MAS`ULIYATI CHEKLANGAN JAMIYATI | I20: 0 | J20: 1 | K20: 30 | L20: NASRITDINOV ZAVKIDDIN NURITDINOVICH | M20: 31506640211647 | N20: NASRITDINOV ZAVKIDDIN NURITDINOVICH | O20: 888289009 | P20: 31506640211647 | R20: 1 | S20: NASRITDINOV ZAVKIDDIN NURITDINOVICH | T20: 31506640211647 | U20: 888289009 | V20: YTT | W20: AOS | X20: VG544170029912 | AA20: Faol | AF20: 0 | AG20: 0 | AH20: 0 | AI20: 0 | AJ20: 0 | AK20: 0 | AL20: 18 | AM20: 9.75 | AN20: 0 | AO20: =+VLOOKUP(Q20,[1]умумий!$P$4:$EB$787,117,0) -> #N/A
A21: 17 | B21: Blok A | C21: 3-do'kon | D21: 10:10:40:01:01:0011/0012 | E21: Alimov Ulugbek Rustamovich | F21: 30809640040022 | G21: 951773373 | H21: PREMIUM PRIME SERVICE" MAS`ULIYATI CHEKLANGAN JAMIYATI | I21: 180 | J21: 1 | K21: 40 | L21: "Intouch" Mchj | M21: 31112880221722 | N21: Shamsutdinov Sunnat Utkurovich | O21: 998990862228 | Q21: 306067924 | R21: 17 | S21: Shamsutdinov Sunnat Utkurovich Shamsiddinov Doston O`tkir O‘g‘li Shamsutdinov Dilshod Utkurovich Nigmanov Nasirullo Muxamatovich Mirsobirov Ibrohim Dilshod O‘g‘li Rixsiyev Jaloliddin Nuriddin O‘g‘li Inog‘Omov Axbor Axror O‘g‘li Abduqahhorov Asadbek Dilshod O‘g‘li Abdug‘Aniyev Abduvali Jaxongir O‘g‘li Muxamedaliyev Dilshod Muxamedayubovich O‘Ktamov Shovkat Ibrohim O‘g‘li Mahmudov Bobur Bahtiyor O‘g‘li Qudratullayev Azizjon Rashid O‘g‘li Sayfullayev Sultonmurod Kaxramon O‘g‘li Xabibullayev Muxammad Uktam O‘g‘li Xamidullayev Dilshod Muzrab O‘g‘li Xayrullayev Sarvarjon Sayfulla O‘g‘li | T21: 998756541 | U21: 904337777 900047000 933984606 000000000 900957777 997949112 990505959 970364404 935811016 977699299 955555800 977333273 946810806 777271334 990857293 977096315 900510009 | V21: Yuridik | W21: QQS | X21: VG300750020148 | AA21: Faol | AF21: 733.4 | AG21: 2002 | AH21: 71.5 | AI21: 190 | AJ21: 0.7 | AK21: 6 | AL21: 131 | AM21: 2448.1919 | AN21: 0 | AO21: =+VLOOKUP(Q21,[1]умумий!$P$4:$EB$787,117,0) -> 0
A22: 18 | B22: Blok A | C22: 3-do'kon | D22: 10:10:40:01:01:0011/0012 | E22: Alimov Ulugbek Rustamovich | F22: 30809640040022 | G22: 951773373 | H22: PREMIUM PRIME SERVICE" MCHJ | I22: 0 | J22: 1 | K22: 20 | L22: AZIZJON QUDRATULLAYEV RASHID O‘G‘LI | M22: 52303036610029 | N22: AZIZJON QUDRATULLAYEV RASHID O‘G‘LI | O22: 998756541 | P22: 52303036610029 | R22: 1 | S22: AZIZJON QUDRATULLAYEV RASHID O‘G‘LI | T22: 52303036610029 | U22: 998756541 | V22: YTT | W22: AOS | X22: LG420211622155 | AA22: Faol | AF22: 123.2 | AG22: 44 | AH22: 7.5 | AI22: 3 | AJ22: 0 | AK22: 0 | AL22: 0 | AM22: 0 | AN22: 0 | AO22: =+VLOOKUP(Q22,[1]умумий!$P$4:$EB$787,117,0) -> #N/A
A23: 19 | B23: Blok A | C23: 3-do'kon | D23: 10:10:40:01:01:0011/0012 | E23: Alimov Ulugbek Rustamovich | F23: 30809640040022 | G23: 951773373 | H23: PREMIUM PRIME SERVICE" MCHJ | I23: 0 | J23: 1 | K23: 40 | L23: Kudratov Murodjon Xikmatullayevich | M23: 31208740220018 | N23: Kudratov Murodjon Xikmatullayevich | O23: 997201133 | P23: 31208740220018 | R23: 1 | S23: Kudratov Murodjon Xikmatullayevich | T23: 31208740220018 | U23: 997201133 | V23: YTT | W23: AOS | X23: LG420211621166 | AA23: Faol | AF23: 23.3 | AG23: 24 | AH23: 2.8 | AI23: 8 | AJ23: 0 | AK23: 0 | AL23: 0 | AM23: 0 | AN23: 0 | AO23: =+VLOOKUP(Q23,[1]умумий!$P$4:$EB$787,117,0) -> #N/A
A24: 20 | B24: Blok A | C24: 3-do'kon | D24: 10:10:40:01:01:0011/0012 | E24: Alimov Ulugbek Rustamovich | F24: 30809640040022 | G24: 951773373 | H24: PREMIUM PRIME SERVICE" MAS`ULIYATI CHEKLANGAN JAMIYATI | I24: 0 | J24: 1 | K24: 40 | L24: Movlonxo‘Jayev Rustam Davron O'g'li | M24: 32410986610042 | N24: Movlonxo‘Jayev Rustam Davron O'g'li | O24: +998935443445 | P24: 32410986610042 | R24: 5 | S24: Turdushadjiev Ilzat Azatovich Nabiev Atxambek Baxodir O‘g‘li Xakimov Umid Niyazovich Yusupov Farxod Sadikdjanovich Narkobelov Otabek Abduraxim O‘g‘li | T24: 31301870770058 30812956610021 32912830220080 30112770250091 30405920171828 | U24: 997100001 974344686 974438282 000000000 999350030 | V24: YTT | W24: AOS | X24: YZ231006000696 | AA24: Faol | AF24: 340.9 | AG24: 1681 | AH24: 44.7 | AI24: 390 | AJ24: 2.2 | AK24: 29 | AL24: 0 | AM24: 0 | AN24: 0 | AO24: =+VLOOKUP(Q24,[1]умумий!$P$4:$EB$787,117,0) -> #N/A
A25: 21 | B25: Blok A | C25: 3-do'kon | D25: 10:10:40:01:01:0011/0012 | E25: Alimov Ulugbek Rustamovich | F25: 30809640040022 | G25: 951773373 | H25: PREMIUM PRIME SERVICE" MAS`ULIYATI CHEKLANGAN JAMIYATI | I25: 0 | J25: 1 | K25: 40 | L25: Sodiqjonov Faxriddin Farhod O'g'li | M25: 51412066750038 | N25: Sodiqjonov Faxriddin Farhod O'g'li | O25: +998938943333 | P25: 51412066750038 | R25: 5 | S25: Kudratov Murojon Xikmatullaevich Raimdjanov Ulugbek Abdusalomovich Tokniyozov Rustam Turdiaxunovich Saydullaev Shuxrat Shovkat O’g’li Asadullaev Farrux Abdullo O’g’li | T25: 31208740220018 31810881240138 31104786590013 31410910171725 51007036750031 | U25: 997201133 931351818 990038880 998305133 000000000 | V25: YTT | W25: AOS | X25: LG420211639801 | AA25: Faol | AF25: 247.5 | AG25: 1377 | AH25: 40.4 | AI25: 289 | AJ25: 5.1 | AK25: 37 | AL25: 0 | AM25: 0 | AN25: 0 | AO25: =+VLOOKUP(Q25,[1]умумий!$P$4:$EB$787,117,0) -> #N/A
A26: 22 | B26: Blok A | C26: 4-do'kon | D26: 10:10:40:01:01:0011/0012 | E26: Alimov Ulugbek Rustamovich | F26: 30809640040022 | G26: 951773373 | H26: PREMIUM PRIME SERVICE" MAS`ULIYATI CHEKLANGAN JAMIYATI | I26: 180 | J26: 1 | K26: 15 | L26: ЧП "NODIR-ALI-FAYZ SERVICE" | M26: 32512860220056 | N26: SHAYXOV NODIR NIGMATULLAYEVICH | O26: 977028686 | Q26: 307047971 | R26: 1 | S26: SHAYXOV NODIR NIGMATULLAYEVICH | T26: 32512860220056 | U26: 977028686 | V26: Yuridik | W26: AOS | X26: 0 | AA26: Faol | AF26: 0 | AG26: 0 | AH26: 0 | AI26: 0 | AJ26: 0 | AK26: 0 | AL26: 14 | AM26: 84 | AN26: 0 | AO26: =+VLOOKUP(Q26,[1]умумий!$P$4:$EB$787,117,0) -> 0
A27: 23 | B27: Blok A | C27: 4-do'kon | D27: 10:10:40:01:01:0011/0012 | E27: Alimov Ulugbek Rustamovich | F27: 30809640040022 | G27: 951773373 | H27: PREMIUM PRIME SERVICE" MAS`ULIYATI CHEKLANGAN JAMIYATI | I27: 0 | J27: 1 | K27: 15 | L27: `OPEN SHOP` MCHJ | M27: 30410860240026 | N27: KARIMJONOV SARDOR ABDUXALIL O‘G‘LI | O27: 998357313 | Q27: 307095613 | R27: 1 | S27: KARIMJONOV SARDOR ABDUXALIL O‘G‘LI | T27: 30410860240026 | U27: 998357313 | V27: Yuridik | W27: QQS | X27: YZ231006043301 | AF27: 573.7 | AG27: 131 | AH27: 4 | AI27: 1 | AJ27: 0 | AK27: 0 | AL27: 126 | AM27: 22601.465 | AN27: 0 | AO27: =+VLOOKUP(Q27,[1]умумий!$P$4:$EB$787,117,0) -> 0
A28: 24 | B28: Blok A | C28: 4-do'kon | D28: 10:10:40:01:01:0011/0012 | E28: Alimov Ulugbek Rustamovich | F28: 30809640040022 | G28: 951773373 | H28: PREMIUM PRIME SERVICE" MAS`ULIYATI CHEKLANGAN JAMIYATI | I28: 0 | J28: 1 | K28: 15 | L28: `OPEN SHOP` MCHJ | M28: 30410860240026 | N28: KARIMJONOV SARDOR ABDUXALIL O‘G‘LI | O28: 998357313 | Q28: 307095613 | R28: 1 | S28: KARIMJONOV SARDOR ABDUXALIL O‘G‘LI | T28: 30410860240026 | U28: 998357313 | V28: Yuridik | W28: QQS | X28: NA000000016613 | AA28: Faol | AF28: 1071.4 | AG28: 151 | AH28: 0 | AI28: 0 | AJ28: 0 | AK28: 0 | AL28: 273 | AM28: 39886.169 | AN28: 0 | AO28: =+VLOOKUP(Q28,[1]умумий!$P$4:$EB$787,117,0) -> 0
A29: 25 | B29: Blok A | C29: 4-do'kon | D29: 10:10:40:01:01:0011/0012 | E29: Alimov Ulugbek Rustamovich | F29: 30809640040022 | G29: 951773373 | H29: PREMIUM PRIME SERVICE" MAS`ULIYATI CHEKLANGAN JAMIYATI | I29: 0 | J29: 1 | K29: 15 | L29: Rasulov Maxmudjon Dexkanbayevich | M29: 30303720221421 | N29: Rasulov Maxmudjon Dexkanbayevich | O29: 946600767 | P29: 30303720221421 | R29: 1 | S29: Rasulov Maxmudjon Dexkanbayevich | T29: 30303720221421 | U29: 946600767 | V29: YTT | W29: AOS | X29: LG420211621167 | AA29: Faol | AF29: 35.8 | AG29: 35 | AH29: 7.6 | AI29: 7 | AJ29: 0 | AK29: 0 | AL29: 0 | AM29: 0 | AN29: 0 | AO29: =+VLOOKUP(Q29,[1]умумий!$P$4:$EB$787,117,0) -> #N/A
A30: 26 | B30: Blok A | C30: 4-do'kon | D30: 10:10:40:01:01:0011/0012 | E30: Alimov Ulugbek Rustamovich | F30: 30809640040022 | G30: 951773373 | H30: PREMIUM PRIME SERVICE" MAS`ULIYATI CHEKLANGAN JAMIYATI | I30: 0 | J30: 1 | K30: 15 | L30: NABIYEV IZZATULLA SUNNATULLO O‘G‘LI | M30: 30803986610028 | N30: NABIYEV IZZATULLA SUNNATULLO O‘G‘LI | O30: 770044040 | P30: 30803986610028 | R30: 1 | S30: NABIYEV IZZATULLA SUNNATULLO O‘G‘LI | T30: 30803986610028 | U30: 770044040 | V30: YTT | W30: AOS | X30: LG420211621168 | AA30: Faol | AF30: 27.6 | AG30: 127 | AH30: 5.6 | AI30: 29 | AJ30: 1 | AK30: 8 | AL30: 0 | AM30: 0 | AN30: 0 | AO30: =+VLOOKUP(Q30,[1]умумий!$P$4:$EB$787,117,0) -> #N/A
A31: 27 | B31: Blok A | C31: 4-do'kon | D31: 10:10:40:01:01:0011/0012 | E31: Alimov Ulugbek Rustamovich | F31: 30809640040022 | G31: 951773373 | H31: PREMIUM PRIME SERVICE" MAS`ULIYATI CHEKLANGAN JAMIYATI | I31: 0 | J31: 1 | K31: 15 | L31: Shoxzodbek Yoqubjonov Ilhomjon O'g'li | M31: 30904932140115 | N31: Shoxzodbek Yoqubjonov Ilhomjon O'g'li | O31: 900000000 | P31: 30904932140115 | R31: 1 | S31: Shoxzodbek Yoqubjonov Ilhomjon O'g'li | T31: 30904932140115 | U31: 900000000 | V31: YTT | W31: AOS | X31: VG343420021079 | AA31: Faol | AF31: 167.6 | AG31: 51 | AH31: 17.9 | AI31: 7 | AJ31: 0 | AK31: 0 | AL31: 1 | AM31: 5.88 | AN31: 0 | AO31: =+VLOOKUP(Q31,[1]умумий!$P$4:$EB$787,117,0) -> #N/A
A32: 28 | B32: Blok A | C32: 4-do'kon | D32: 10:10:40:01:01:0011/0012 | E32: Alimov Ulugbek Rustamovich | F32: 30809640040022 | G32: 951773373 | H32: PREMIUM PRIME SERVICE" MAS`ULIYATI CHEKLANGAN JAMIYATI | I32: 0 | J32: 1 | K32: 15 | L32: ZUXRIDDINOV SHOXOBIDDIN FAZLIDDIN O‘G‘LI | M32: 31905976670061 | N32: ZUXRIDDINOV SHOXOBIDDIN FAZLIDDIN O‘G‘LI | O32: 907880058 | P32: 31905976670061 | R32: 1 | S32: ZUXRIDDINOV SHOXOBIDDIN FAZLIDDIN O‘G‘LI | T32: 31905976670061 | U32: 907880058 | V32: YTT | W32: AOS | X32: LG420211609406 | AA32: Faol | AF32: 40.9 | AG32: 26 | AH32: 0.1 | AI32: 1 | AJ32: 0 | AK32: 0 | AL32: 0 | AM32: 0 | AN32: 0 | AO32: =+VLOOKUP(Q32,[1]умумий!$P$4:$EB$787,117,0) -> #N/A
A33: 29 | B33: Blok A | C33: 4-do'kon | D33: 10:10:40:01:01:0011/0012 | E33: Alimov Ulugbek Rustamovich | F33: 30809640040022 | G33: 951773373 | H33: PREMIUM PRIME SERVICE" MAS`ULIYATI CHEKLANGAN JAMIYATI | I33: 0 | J33: 1 | K33: 15 | L33: IBROHIMOV JO‘RABEK AHMADJON O‘G‘LI | M33: 32109986540032 | N33: IBROHIMOV JO‘RABEK AHMADJON O‘G‘LI | O33: 909338885 | P33: 32109986540032 | R33: 1 | S33: IBROHIMOV JO‘RABEK AHMADJON O‘G‘LI | T33: 32109986540032 | U33: 909338885 | V33: YTT | W33: AOS | X33: LG420211638029 | AA33: Faol | AF33: 229.6 | AG33: 37 | AH33: 18.3 | AI33: 4 | AJ33: 0 | AK33: 0 | AL33: 32 | AM33: 67.17 | AN33: 1 | AO33: =+VLOOKUP(Q33,[1]умумий!$P$4:$EB$787,117,0) -> #N/A
A34: 30 | B34: Blok A | C34: 4-do'kon | D34: 10:10:40:01:01:0011/0012 | E34: Alimov Ulugbek Rustamovich | F34: 30809640040022 | G34: 951773373 | H34: PREMIUM PRIME SERVICE" MAS`ULIYATI CHEKLANGAN JAMIYATI | I34: 0 | J34: 1 | K34: 15 | L34: Toxirov Davron Xaydar O'g'li | M34: 32404910600036 | N34: Toxirov Davron Xaydar O'g'li | O34: +998331019999 | P34: 32404910600036 | R34: 4 | S34: QAMBAROV AZIZJON AKMAL O‘G‘LI G‘ULOMOV XASAN G‘OFURJON O‘G‘LI MUXAMEDOV SHAXZOD UKTAMOVICH ABDURAXIMOV ASADBEK ABDURAZZOQ O‘G‘LI | T34: 53007046750058 31511840290024 31708880070039 50402056620022 | U34: 0998977401500 998909323640 998998008383 998974230204 | V34: YTT | W34: AOS | X34: LG420211622505 | AA34: Faol | AF34: 71.3 | AG34: 96 | AH34: 2.2 | AI34: 2 | AJ34: 0 | AK34: 0 | AL34: 1 | AM34: 0.03 | AN34: 0 | AO34: =+VLOOKUP(Q34,[1]умумий!$P$4:$EB$787,117,0) -> #N/A
A35: 31 | B35: Blok A | C35: 4-do'kon | D35: 10:10:40:01:01:0011/0012 | E35: Alimov Ulugbek Rustamovich | F35: 30809640040022 | G35: 951773373 | H35: PREMIUM PRIME SERVICE" MAS`ULIYATI CHEKLANGAN JAMIYATI | I35: 0 | J35: 1 | K35: 15 | L35: Tojiboyev Abbosjon Umidjon O'g'li | M35: 50304026520049 | N35: Tojiboyev Abbosjon Umidjon O'g'li | O35: +998998151711 | P35: 50304026520049 | R35: 1 | S35: RAXIMOV OYBEK ULUG‘BEK O‘G‘LI | T35: 52106036610026 | U35: 998900156240 | V35: YTT | W35: AOS | X35: VG298430010687 | AA35: Faol | AF35: 97.6 | AG35: 126 | AH35: 5.9 | AI35: 20 | AJ35: 0.7 | AK35: 3 | AL35: 1 | AM35: 1.52 | AN35: 0 | AO35: =+VLOOKUP(Q35,[1]умумий!$P$4:$EB$787,117,0) -> #N/A
A36: 32 | B36: Blok A | C36: 4-do'kon | D36: 10:10:40:01:01:0011/0012 | E36: Alimov Ulugbek Rustamovich | F36: 30809640040022 | G36: 951773373 | H36: PREMIUM PRIME SERVICE" MAS`ULIYATI CHEKLANGAN JAMIYATI | I36: 0 | J36: 1 | K36: 15 | L36: AXMADALIYEV ABU-BAKIR ALISHER O‘G‘LI | M36: 50610006610047 | N36: AXMADALIYEV ABU-BAKIR ALISHER O‘G‘LI | O36: 940555514 | P36: 50610006610047 | R36: 1 | S36: AXMADALIYEV ABU-BAKIR ALISHER O‘G‘LI | T36: 50610006610047 | U36: 940555514 | V36: YTT | W36: AOS | X36: 0 | AA36: Faol | AF36: 0 | AG36: 0 | AH36: 0 | AI36: 0 | AJ36: 0 | AK36: 0 | AL36: 0 | AM36: 0 | AN36: 0 | AO36: =+VLOOKUP(Q36,[1]умумий!$P$4:$EB$787,117,0) -> #N/A
A37: 33 | B37: Blok A | C37: 4-do'kon | D37: 10:10:40:01:01:0011/0012 | E37: Alimov Ulugbek Rustamovich | F37: 30809640040022 | G37: 951773373 | H37: PREMIUM PRIME SERVICE" MAS`ULIYATI CHEKLANGAN JAMIYATI | I37: 0 | J37: 1 | K37: 15 | L37: Tursunov Dilnur Dilshod O'g'li | M37: 50905066620030 | N37: Tursunov Dilnur Dilshod O'g'li | O37: +998940704343 | P37: 50905066620030 | R37: 3 | S37: OBIDJONOV MUXAMMADALI OMILJON O‘G‘LI NARMAMATOV SHUXRATJON MAMADALIYEVICH ALIYEV MAHMUDJON IBROHIM O‘G‘LI | T37: 53105086540052 31512892940037 32704985970035 | U37: 998908287654 998909433118 998977100023 | V37: YTT | W37: AOS | X37: LG420211622506 | AA37: Faol | AF37: 45.1 | AG37: 50 | AH37: 1.4 | AI37: 3 | AJ37: 0.5 | AK37: 1 | AL37: 1 | AM37: 0.01 | AN37: 0 | AO37: =+VLOOKUP(Q37,[1]умумий!$P$4:$EB$787,117,0) -> #N/A
A38: 34 | B38: Blok A | C38: 4-do'kon | D38: 10:10:40:01:01:0011/0012 | E38: Alimov Ulugbek Rustamovich | F38: 30809640040022 | G38: 951773373 | H38: PREMIUM PRIME SERVICE" MAS`ULIYATI CHEKLANGAN JAMIYATI | I38: 0 | J38: 1 | K38: 15 | L38: Sobirjonov Shukurjon Sharifjon O'g'li | M38: 52107006610066 | N38: Sobirjonov Shukurjon Sharifjon O'g'li | O38: 903208696 | P38: 52107006610066 | R38: 1 | S38: Sobirjonov Shukurjon Sharifjon O'g'li | T38: 52107006610066 | U38: 903208696 | V38: YTT | W38: AOS | X38: 0 | AA38: Faol | AF38: 0 | AG38: 0 | AH38: 0 | AI38: 0 | AJ38: 0 | AK38: 0 | AL38: 0 | AM38: 0 | AN38: 0 | AO38: =+VLOOKUP(Q38,[1]умумий!$P$4:$EB$787,117,0) -> #N/A
A39: 35 | B39: Blok A | C39: 5-do'kon | D39: 10:10:40:01:01:0011/0012 | E39: Alimov Ulugbek Rustamovich | F39: 30809640040022 | G39: 951773373 | H39: PREMIUM PRIME SERVICE" MAS`ULIYATI CHEKLANGAN JAMIYATI | I39: 180 | J39: 1 | K39: 20 | L39: Igamberdiyev Umarjon Mamurjon O'g'li | M39: 50610036610017 | N39: Igamberdiyev Umarjon Mamurjon O'g'li | O39: 959054505 | P39: 50610036610017 | R39: 1 | S39: Igamberdiyev Umarjon Mamurjon O'g'li | T39: 50610036610017 | U39: 959054505 | V39: YTT | W39: QQS | X39: LG420211621216 | AA39: Faol | AF39: 148.3 | AG39: 177 | AH39: 31 | AI39: 46 | AJ39: 0 | AK39: 0 | AL39: 0 | AM39: 0 | AN39: 0 | AO39: =+VLOOKUP(Q39,[1]умумий!$P$4:$EB$787,117,0) -> #N/A
A40: 743 | B40: Blok A | C40: 5-do'kon | D40: 10:10:40:01:01:0011/0012 | E40: Alimov Ulugbek Rustamovich | F40: 30809640040022 | G40: 951773373 | H40: PREMIUM PRIME SERVICE" MAS`ULIYATI CHEKLANGAN JAMIYATI | I40: 0 | J40: 1 | K40: 20 | L40: RAHIMJONOV ULUG‘BEK ABDUVAHOB O‘G‘LI | M40: 31211940210071 | N40: RAHIMJONOV ULUG‘BEK ABDUVAHOB O‘G‘LI | P40: 31211940210071 | Q40: 309280120 | R40: 1 | S40: RAHIMJONOV ULUG‘BEK ABDUVAHOB O‘G‘LI | T40: 31211940210071 | V40: YTT | W40: AOS | X40: LG420211633912 | AF40: 43.9 | AG40: 286 | AH40: 6 | AI40: 67 | AJ40: 0 | AK40: 0 | AL40: 6 | AM40: 200.40433 | AN40: 0 | AO40: =+VLOOKUP(Q40,[1]умумий!$P$4:$EB$787,117,0) -> 0
A41: 36 | B41: Blok A | C41: 5-do'kon | D41: 10:10:40:01:01:0011/0012 | E41: Alimov Ulugbek Rustamovich | F41: 30809640040022 | G41: 951773373 | H41: PREMIUM PRIME SERVICE" MAS`ULIYATI CHEKLANGAN JAMIYATI | I41: 0 | J41: 1 | K41: 20 | L41: Ataxanov Nodirbek Nozimovich | M41: 32412820770019 | N41: Ataxanov Nodirbek Nozimovich | O41: +998983671982 | P41: 32412820770019 | R41: 5 | S41: Abdullaxatov Xusan Abduzabixilla O‘g‘li Raximjonov Shaxzod Baxrom O‘g‘li Ubaydullaev Lutfulla Sayfullaevich Tadjibaev Muxammad Muxtorovich Tolipov Abror Avzal O‘g‘li | T41: 50511046600033 50603046610016 31001820222272 31009854320041 30511910211112 | U41: 332022233 946753634 977734473 932704944 977005005 | V41: YTT | W41: AOS | X41: UZ201125124435 | AA41: Faol | AF41: 311.9 | AG41: 275 | AH41: 0 | AI41: 0 | AJ41: 0 | AK41: 0 | AL41: 0 | AM41: 0 | AN41: 0 | AO41: =+VLOOKUP(Q41,[1]умумий!$P$4:$EB$787,117,0) -> #N/A
...

Sheet Лист1
A1: T/R | B1: Blok | C1: Do'kon raqami | D1: Do'kon egasi F.I.Sh | E1: JSHSHIR raqami | F1: Telefon raqami | G1: Do'kon egasiga tegishli MCHJ nomi | H1: Do'kon umumiy maydoni | I1: ijaraga olgan tadbirkor soni | J1: Ijaraga berilgan maydoni kv.m | K1: Faoliyat olib borayotgan Tadbirkorlik subyektining nomi | L1: Faoliyat olib borayotgan Tadbirkorlik subyekti Rahbarining JSHSHIR raqami | M1: Faoliyat olib borayotgan Tadbirkorlik subyekti Rahbarining F.I.SH | N1: Faoliyat olib borayotgan Tadbirkorlik subyekti Rahbarining Telefon raqami | O1: Faoliyat olib borayotgan tadbirkorlik subyektining JSHSHIR raqami | P1: Faoliyat olib borayotgan tadbirkorlik subyektining STIR raqami | Q1: Faoliyat olib borayotgan Tadbirkorlik subyektida ishlaydigan xodimlar soni | R1: Faoliyat olib borayotgan Tadbirkorlik subyektida ishlaydigan xodimlar, F.I.SH raqami | S1: Faoliyat olib borayotgan Tadbirkorlik subyektida ishlaydigan xodimlar, JSHSHIR raqami | T1: Faoliyat olib borayotgan Tadbirkorlik subyektida ishlaydigan xodimlar, Telefon raqami | U1: Tadbirkorlik turi | V1: Soliq turi (QQS, Aylanmadan olinadigan soliq) | W1: Kassa apparat raqami | X1: Tadbirkorlik Subyekti holati (FAOL/NOFAOL) | Y1: Yong'in xavfsizlik darajasi
A3: 1 | B3: Blok A | C3: 1-do'kon | D3: Alimov Ulugbek Rustamovich | E3: 30809640040022 | F3: 951773373 | G3: PREMIUM PRIME SERVICE" MAS`ULIYATI CHEKLANGAN JAMIYATI | H3: 180 | I3: 1 | J3: 40 | K3: "NETTRA" MCHJ | L3: 52709046530021 | M3: YOQUBOV SUNNATILLA NODIR O‘G‘LI | N3: 333173003 | P3: 312658448 | Q3: 1 | R3: YOQUBOV SUNNATILLA NODIR O‘G‘LI | S3: 52709046530021 | T3: 312658448 | U3: Yuridik | V3: AOS | W3: LG420211628643 | X3: Faol
A4: 2 | B4: Blok A | C4: 1-do'kon | D4: Alimov Ulugbek Rustamovich | E4: 30809640040022 | F4: 951773373 | G4: PREMIUM PRIME SERVICE" MAS`ULIYATI CHEKLANGAN JAMIYATI | H4: 0 | I4: 1 | J4: 40 | K4: Xakimov Botir Baxtiyarovich | L4: 30105830210098 | M4: Xakimov Botir Baxtiyarovich | N4: 977751515 | O4: 30105830210098 | Q4: 5 | R4: МАРАСИЛОВ ОЙБЕК УСМАНОВИЧ | S4: 31705862180016 50204056590048 50307006610055 32801901951122 32005985970048 | T4: 936688000 000000000 000000000 940057111 940527799 | U4: YTT | V4: AOS | W4: VG300750002569 | X4: Faol | Y4: 0
A5: 3 | B5: Blok A | C5: 1-do'kon | D5: Alimov Ulugbek Rustamovich | E5: 30809640040022 | F5: 951773373 | G5: PREMIUM PRIME SERVICE" MAS`ULIYATI CHEKLANGAN JAMIYATI | H5: 0 | I5: 1 | J5: 40 | K5: Islombekov Otabek Rustambek O'g'li | L5: 30208940330022 | M5: Islombekov Otabek Rustambek O'g'li | N5: +998946447750 | O5: 30208940330022 | Q5: 5 | R5: ISMANOV MAXMUDJON MUROD O‘G‘LI | S5: 32608950260036 50201048660055 31212840220049 51303046730028 50202006590023 | T5: 947945599 000000000 000000000 935541343 957876996 | U5: YTT | V5: AOS | W5: LG420211621180 | X5: Faol | Y5: =VLOOKUP(L5,'[2]йил бошидан'!$B$5:$C$2923,2,0) -> 15.93
A6: 4 | B6: Blok A | C6: 1-do'kon | D6: Alimov Ulugbek Rustamovich | E6: 30809640040022 | F6: 951773373 | G6: PREMIUM PRIME SERVICE" MAS`ULIYATI CHEKLANGAN JAMIYATI | H6: 0 | I6: 1 | J6: 40 | K6: МАРАСИЛОВ ОЙБЕК УСМАНОВИЧ | L6: 32909770170047 | M6: МАРАСИЛОВ ОЙБЕК УСМАНОВИЧ | N6: 999937216 | O6: 32909770170047 | Q6: 1 | R6: МАРАСИЛОВ ОЙБЕК УСМАНОВИЧ | S6: 32909770170047 | T6: 999937216 | U6: YTT | V6: AOS | W6: UZ201125124416 | X6: Faol | Y6: 0
A7: 5 | B7: Blok A | C7: 1-do'kon | D7: Alimov Ulugbek Rustamovich | E7: 30809640040022 | F7: 951773373 | G7: PREMIUM PRIME SERVICE" MAS`ULIYATI CHEKLANGAN JAMIYATI | H7: 0 | I7: 1 | J7: 20 | K7: ISMANOV MAXMUDJON MUROD O‘G‘LI | L7: 50608006610020 | M7: ISMANOV MAXMUDJON MUROD O‘G‘LI | N7: 941115544 | O7: 50608006610020 | Q7: 1 | R7: ISMANOV MAXMUDJON MUROD O‘G‘LI | S7: 50608006610020 | T7: 941115544 | U7: YTT | V7: AOS | W7: LG420211621377 | X7: Faol | Y7: =VLOOKUP(L7,'[2]йил бошидан'!$B$5:$C$2923,2,0) -> 4.4
A8: 6 | B8: Blok A | C8: 2-do'kon | D8: AbdumalikovAkmal Pulat o'g'li | E8: 51010066600018 | F8: 935272727 | H8: 180 | I8: 1 | J8: 15 | K8: FIRDAVS-ZOHID SAVDO | L8: 43011920330011 | M8: USMONOVA MUQADDAS SHUXRATJONOVNA | N8: 958598008 | P8: 301758598 | Q8: 1 | R8: USMONOVA MUQADDAS SHUXRATJONOVNA | S8: 43011920330011 | T8: 958598008 | U8: Yuridik | V8: AOS | W8: LG420211601706 | X8: Faol
A9: 7 | B9: Blok A | C9: 2-do'kon | D9: AbdumalikovAkmal Pulat o'g'li | E9: 51010066600018 | F9: 935272727 | H9: 0 | I9: 1 | J9: 15 | K9: USMANOV UKTAMJON XAMIDOVICH | L9: 30405602100034 | M9: USMANOV UKTAMJON XAMIDOVICH | N9: 955535040 | O9: 30405602100034 | Q9: 1 | R9: USMANOV UKTAMJON XAMIDOVICH | S9: 30405602100034 | T9: 955535040 | U9: YTT | V9: AOS | X9: Faol | Y9: 0
A10: 8 | B10: Blok A | C10: 2-do'kon | D10: AbdumalikovAkmal Pulat o'g'li | E10: 51010066600018 | F10: 935272727 | H10: 0 | I10: 1 | J10: 15 | K10: SALIYEV ULUG‘BEK BAXTIYOR O‘G‘LI | L10: 30601910171605 | M10: SALIYEV ULUG‘BEK BAXTIYOR O‘G‘LI | N10: 951107577 | O10: 30601910171605 | Q10: 1 | R10: SALIYEV ULUG‘BEK BAXTIYOR O‘G‘LI | S10: 30601910171605 | T10: 951107577 | U10: YTT | V10: AOS | X10: Faol | Y10: 0
A11: 9 | B11: Blok A | C11: 2-do'kon | D11: AbdumalikovAkmal Pulat o'g'li | E11: 51010066600018 | F11: 935272727 | H11: 0 | I11: 1 | J11: 15 | K11: BERDIYOROV ASROR SHUHRAT O‘G‘LI | L11: 31208966580017 | M11: BERDIYOROV ASROR SHUHRAT O‘G‘LI | N11: 935475515 | O11: 31208966580017 | Q11: 1 | R11: BERDIYOROV ASROR SHUHRAT O‘G‘LI | S11: 31208966580017 | T11: 935475515 | U11: YTT | V11: AOS | W11: LG420211610963 | X11: Faol | Y11: 0
A12: 10 | B12: Blok A | C12: 2-do'kon | D12: AbdumalikovAkmal Pulat o'g'li | E12: 51010066600018 | F12: 935272727 | H12: 0 | I12: 1 | J12: 15 | K12: Abduraimov Mamurjon Abduxamidovich | L12: 32005810020025 | M12: Abduraimov Mamurjon Abduxamidovich | N12: 981211900 | O12: 32005810020025 | Q12: 4 | R12: ANVAROV OYBEK A’ZAMJON O‘G‘LI KOMILJONOV KAMRONBEK SANJARBEK O‘G‘LI XAYRIDDINOV ABDULLOH ZUHRIDDIN O'G'LI TOIRXONOV IBROHIMXON FATTOXXON O‘G‘LI | S12: 30708942190047 52310066750034 51605048680034 50906016750023 | T12: 998981211900 998981211900 998900000000 998974636446 | U12: YTT | V12: AOS | W12: LG420211629211 | X12: Faol | Y12: 0
A13: 11 | B13: Blok A | C13: 2-do'kon | D13: AbdumalikovAkmal Pulat o'g'li | E13: 51010066600018 | F13: 935272727 | H13: 0 | I13: 1 | J13: 15 | K13: AXMADJON TALIPOV ABDUXAMIDOVICH | L13: 32704700220023 | M13: AXMADJON TALIPOV ABDUXAMIDOVICH | N13: 977705250 | O13: 32704700220023 | Q13: 1 | R13: AXMADJON TALIPOV ABDUXAMIDOVICH | S13: 32704700220023 | T13: 977705250 | U13: YTT | V13: AOS | W13: NA000000028602 | X13: Faol | Y13: 0
A14: 12 | B14: Blok A | C14: 2-do'kon | D14: AbdumalikovAkmal Pulat o'g'li | E14: 51010066600018 | F14: 935272727 | H14: 0 | I14: 1 | J14: 15 | K14: ISMOILOV ABDULAZIZ RAHMONJON O‘G‘LI | L14: 32709966530013 | M14: ISMOILOV ABDULAZIZ RAHMONJON O‘G‘LI | N14: 977488267 | O14: 32709966530013 | Q14: 1 | R14: ISMOILOV ABDULAZIZ RAHMONJON O‘G‘LI | S14: 32709966530013 | T14: 977488267 | U14: YTT | V14: AOS | X14: Faol | Y14: =VLOOKUP(L14,'[2]йил бошидан'!$B$5:$C$2923,2,0) -> 29.56
A15: 13 | B15: Blok A | C15: 2-do'kon | D15: AbdumalikovAkmal Pulat o'g'li | E15: 51010066600018 | F15: 935272727 | H15: 0 | I15: 1 | J15: 15 | K15: XUSANJON UCHKUNOV UTKUR O‘G‘LI | L15: 50205006610041 | M15: XUSANJON UCHKUNOV UTKUR O‘G‘LI | N15: 946673088 | O15: 50205006610041 | Q15: 1 | R15: XUSANJON UCHKUNOV UTKUR O‘G‘LI | S15: 50205006610041 | T15: 946673088 | U15: YTT | V15: AOS | W15: LG420211621163 | X15: Faol | Y15: =VLOOKUP(L15,'[2]йил бошидан'!$B$5:$C$2923,2,0) -> 14.94
A16: 14 | B16: Blok A | C16: 2-do'kon | D16: AbdumalikovAkmal Pulat o'g'li | E16: 51010066600018 | F16: 935272727 | H16: 0 | I16: 1 | J16: 15 | K16: SA’DULLAYEV HOTAMJON SHAVKATJON O‘G‘LI | L16: 50602016500014 | M16: SA’DULLAYEV HOTAMJON SHAVKATJON O‘G‘LI | N16: 990370761 | O16: 50602016500014 | Q16: 1 | R16: SA’DULLAYEV HOTAMJON SHAVKATJON O‘G‘LI | S16: 50602016500014 | T16: 990370761 | U16: YTT | V16: AOS | W16: LG420211609130 | X16: Faol | Y16: 0
A17: 15 | B17: Blok A | C17: 2-do'kon | D17: AbdumalikovAkmal Pulat o'g'li | E17: 51010066600018 | F17: 935272727 | H17: 0 | I17: 1 | J17: 15 | K17: Voxidov Abdulloh Qodirjon O'g'li | L17: 52403006540012 | M17: Voxidov Abdulloh Qodirjon O'g'li | N17: +998971711001 | O17: 52403006540012 | Q17: 1 | R17: BAXTIYOROV DILMUROD ELDIYOR O‘G‘LI | S17: 52810016500020 | T17: 998971711001 | U17: YTT | V17: AOS | W17: LG420211629139 | X17: Faol | Y17: =VLOOKUP(L17,'[2]йил бошидан'!$B$5:$C$2923,2,0) -> 0
A18: 16 | B18: Blok A | C18: 2-do'kon | D18: AbdumalikovAkmal Pulat o'g'li | E18: 51010066600018 | F18: 935272727 | H18: 0 | I18: 1 | J18: 30 | K18: NASRITDINOV ZAVKIDDIN NURITDINOVICH | L18: 31506640211647 | M18: NASRITDINOV ZAVKIDDIN NURITDINOVICH | N18: 888289009 | O18: 31506640211647 | Q18: 1 | R18: NASRITDINOV ZAVKIDDIN NURITDINOVICH | S18: 31506640211647 | T18: 888289009 | U18: YTT | V18: AOS | X18: Faol | Y18: =VLOOKUP(L18,'[2]йил бошидан'!$B$5:$C$2923,2,0) -> 9.75
A19: 17 | B19: Blok A | C19: 3-do'kon | D19: Alimov Ulugbek Rustamovich | E19: 30809640040022 | F19: 951773373 | G19: PREMIUM PRIME SERVICE" MAS`ULIYATI CHEKLANGAN JAMIYATI | H19: 180 | I19: 1 | J19: 40 | K19: "Intouch" Mchj | L19: 31112880221722 | M19: Shamsutdinov Sunnat Utkurovich | N19: 998990862228 | P19: 306067924 | Q19: 17 | R19: Shamsutdinov Sunnat Utkurovich Shamsiddinov Doston O`tkir O‘g‘li Shamsutdinov Dilshod Utkurovich Nigmanov Nasirullo Muxamatovich Mirsobirov Ibrohim Dilshod O‘g‘li Rixsiyev Jaloliddin Nuriddin O‘g‘li Inog‘Omov Axbor Axror O‘g‘li Abduqahhorov Asadbek Dilshod O‘g‘li Abdug‘Aniyev Abduvali Jaxongir O‘g‘li Muxamedaliyev Dilshod Muxamedayubovich O‘Ktamov Shovkat Ibrohim O‘g‘li Mahmudov Bobur Bahtiyor O‘g‘li Qudratullayev Azizjon Rashid O‘g‘li Sayfullayev Sultonmurod Kaxramon O‘g‘li Xabibullayev Muxammad Uktam O‘g‘li Xamidullayev Dilshod Muzrab O‘g‘li Xayrullayev Sarvarjon Sayfulla O‘g‘li | S19: 998756541 | T19: 904337777 900047000 933984606 000000000 900957777 997949112 990505959 970364404 935811016 977699299 955555800 977333273 946810806 777271334 990857293 977096315 900510009 | U19: Yuridik | V19: QQS | W19: VG300750020148 | X19: Faol
A20: 18 | B20: Blok A | C20: 3-do'kon | D20: Alimov Ulugbek Rustamovich | E20: 30809640040022 | F20: 951773373 | G20: PREMIUM PRIME SERVICE" MCHJ | H20: 0 | I20: 1 | J20: 20 | K20: AZIZJON QUDRATULLAYEV RASHID O‘G‘LI | L20: 52303036610029 | M20: AZIZJON QUDRATULLAYEV RASHID O‘G‘LI | N20: 998756541 | O20: 52303036610029 | Q20: 1 | R20: AZIZJON QUDRATULLAYEV RASHID O‘G‘LI | S20: 52303036610029 | T20: 998756541 | U20: YTT | V20: AOS | W20: LG420211622155 | X20: Faol | Y20: 0
A21: 19 | B21: Blok A | C21: 3-do'kon | D21: Alimov Ulugbek Rustamovich | E21: 30809640040022 | F21: 951773373 | G21: PREMIUM PRIME SERVICE" MCHJ | H21: 0 | I21: 1 | J21: 40 | K21: Kudratov Murodjon Xikmatullayevich | L21: 31208740220018 | M21: Kudratov Murodjon Xikmatullayevich | N21: 997201133 | O21: 31208740220018 | Q21: 1 | R21: Kudratov Murodjon Xikmatullayevich | S21: 31208740220018 | T21: 997201133 | U21: YTT | V21: AOS | W21: LG420211621166 | X21: Faol | Y21: 0
A22: 20 | B22: Blok A | C22: 3-do'kon | D22: Alimov Ulugbek Rustamovich | E22: 30809640040022 | F22: 951773373 | G22: PREMIUM PRIME SERVICE" MAS`ULIYATI CHEKLANGAN JAMIYATI | H22: 0 | I22: 1 | J22: 40 | K22: Movlonxo‘Jayev Rustam Davron O'g'li | L22: 32410986610042 | M22: Movlonxo‘Jayev Rustam Davron O'g'li | N22: +998935443445 | O22: 32410986610042 | Q22: 5 | R22: Turdushadjiev Ilzat Azatovich Nabiev Atxambek Baxodir O‘g‘li Xakimov Umid Niyazovich Yusupov Farxod Sadikdjanovich Narkobelov Otabek Abduraxim O‘g‘li | S22: 31301870770058 30812956610021 32912830220080 30112770250091 30405920171828 | T22: 997100001 974344686 974438282 000000000 999350030 | U22: YTT | V22: AOS | W22: YZ231006000696 | X22: Faol | Y22: 0
A23: 21 | B23: Blok A | C23: 3-do'kon | D23: Alimov Ulugbek Rustamovich | E23: 30809640040022 | F23: 951773373 | G23: PREMIUM PRIME SERVICE" MAS`ULIYATI CHEKLANGAN JAMIYATI | H23: 0 | I23: 1 | J23: 40 | K23: Sodiqjonov Faxriddin Farhod O'g'li | L23: 51412066750038 | M23: Sodiqjonov Faxriddin Farhod O'g'li | N23: +998938943333 | O23: 51412066750038 | Q23: 5 | R23: Kudratov Murojon Xikmatullaevich Raimdjanov Ulugbek Abdusalomovich Tokniyozov Rustam Turdiaxunovich Saydullaev Shuxrat Shovkat O’g’li Asadullaev Farrux Abdullo O’g’li | S23: 31208740220018 31810881240138 31104786590013 31410910171725 51007036750031 | T23: 997201133 931351818 990038880 998305133 000000000 | U23: YTT | V23: AOS | W23: LG420211639801 | X23: Faol | Y23: 0
A24: 22 | B24: Blok A | C24: 4-do'kon | D24: Alimov Ulugbek Rustamovich | E24: 30809640040022 | F24: 951773373 | G24: PREMIUM PRIME SERVICE" MAS`ULIYATI CHEKLANGAN JAMIYATI | H24: 180 | I24: 1 | J24: 15 | K24: ЧП "NODIR-ALI-FAYZ SERVICE" | L24: 32512860220056 | M24: SHAYXOV NODIR NIGMATULLAYEVICH | N24: 977028686 | P24: 307047971 | Q24: 1 | R24: SHAYXOV NODIR NIGMATULLAYEVICH | S24: 32512860220056 | T24: 977028686 | U24: Yuridik | V24: AOS | X24: Faol
A25: 23 | C25: 4-do'kon | D25: Alimov Ulugbek Rustamovich | E25: 30809640040022 | F25: 951773373 | G25: PREMIUM PRIME SERVICE" MAS`ULIYATI CHEKLANGAN JAMIYATI | H25: 0 | I25: 1 | J25: 15 | K25: `OPEN SHOP` MCHJ | L25: 30410860240026 | M25: KARIMJONOV SARDOR ABDUXALIL O‘G‘LI | N25: 998357313 | P25: 307095613 | W25: YZ231006043301
A26: 24 | B26: Blok A | C26: 4-do'kon | D26: Alimov Ulugbek Rustamovich | E26: 30809640040022 | F26: 951773373 | G26: PREMIUM PRIME SERVICE" MAS`ULIYATI CHEKLANGAN JAMIYATI | H26: 0 | I26: 1 | J26: 15 | K26: `OPEN SHOP` MCHJ | L26: 30410860240026 | M26: KARIMJONOV SARDOR ABDUXALIL O‘G‘LI | N26: 998357313 | P26: 307095613 | Q26: 1 | R26: KARIMJONOV SARDOR ABDUXALIL O‘G‘LI | S26: 30410860240026 | T26: 998357313 | U26: Yuridik | V26: AOS | W26: NA000000016613 | X26: Faol
A27: 25 | B27: Blok A | C27: 4-do'kon | D27: Alimov Ulugbek Rustamovich | E27: 30809640040022 | F27: 951773373 | G27: PREMIUM PRIME SERVICE" MAS`ULIYATI CHEKLANGAN JAMIYATI | H27: 0 | I27: 1 | J27: 15 | K27: Rasulov Maxmudjon Dexkanbayevich | L27: 30303720221421 | M27: Rasulov Maxmudjon Dexkanbayevich | N27: 946600767 | O27: 30303720221421 | Q27: 1 | R27: Rasulov Maxmudjon Dexkanbayevich | S27: 30303720221421 | T27: 946600767 | U27: YTT | V27: AOS | W27: LG420211621167 | X27: Faol | Y27: 0
A28: 26 | B28: Blok A | C28: 4-do'kon | D28: Alimov Ulugbek Rustamovich | E28: 30809640040022 | F28: 951773373 | G28: PREMIUM PRIME SERVICE" MAS`ULIYATI CHEKLANGAN JAMIYATI | H28: 0 | I28: 1 | J28: 15 | K28: NABIYEV IZZATULLA SUNNATULLO O‘G‘LI | L28: 30803986610028 | M28: NABIYEV IZZATULLA SUNNATULLO O‘G‘LI | N28: 770044040 | O28: 30803986610028 | Q28: 1 | R28: NABIYEV IZZATULLA SUNNATULLO O‘G‘LI | S28: 30803986610028 | T28: 770044040 | U28: YTT | V28: AOS | W28: LG420211621168 | X28: Faol | Y28: 0
A29: 27 | B29: Blok A | C29: 4-do'kon | D29: Alimov Ulugbek Rustamovich | E29: 30809640040022 | F29: 951773373 | G29: PREMIUM PRIME SERVICE" MAS`ULIYATI CHEKLANGAN JAMIYATI | H29: 0 | I29: 1 | J29: 15 | K29: Shoxzodbek Yoqubjonov Ilhomjon O'g'li | L29: 30904932140115 | M29: Shoxzodbek Yoqubjonov Ilhomjon O'g'li | N29: 900000000 | O29: 30904932140115 | Q29: 1 | R29: Shoxzodbek Yoqubjonov Ilhomjon O'g'li | S29: 30904932140115 | T29: 900000000 | U29: YTT | V29: AOS | W29: VG343420021079 | X29: Faol | Y29: 0
A30: 28 | B30: Blok A | C30: 4-do'kon | D30: Alimov Ulugbek Rustamovich | E30: 30809640040022 | F30: 951773373 | G30: PREMIUM PRIME SERVICE" MAS`ULIYATI CHEKLANGAN JAMIYATI | H30: 0 | I30: 1 | J30: 15 | K30: ZUXRIDDINOV SHOXOBIDDIN FAZLIDDIN O‘G‘LI | L30: 31905976670061 | M30: ZUXRIDDINOV SHOXOBIDDIN FAZLIDDIN O‘G‘LI | N30: 907880058 | O30: 31905976670061 | Q30: 1 | R30: ZUXRIDDINOV SHOXOBIDDIN FAZLIDDIN O‘G‘LI | S30: 31905976670061 | T30: 907880058 | U30: YTT | V30: AOS | W30: LG420211609406 | X30: Faol | Y30: 0
A31: 29 | B31: Blok A | C31: 4-do'kon | D31: Alimov Ulugbek Rustamovich | E31: 30809640040022 | F31: 951773373 | G31: PREMIUM PRIME SERVICE" MAS`ULIYATI CHEKLANGAN JAMIYATI | H31: 0 | I31: 1 | J31: 15 | K31: IBROHIMOV JO‘RABEK AHMADJON O‘G‘LI | L31: 32109986540032 | M31: IBROHIMOV JO‘RABEK AHMADJON O‘G‘LI | N31: 909338885 | O31: 32109986540032 | Q31: 1 | R31: IBROHIMOV JO‘RABEK AHMADJON O‘G‘LI | S31: 32109986540032 | T31: 909338885 | U31: YTT | V31: AOS | W31: LG420211638029 | X31: Faol | Y31: =VLOOKUP(L31,'[2]йил бошидан'!$B$5:$C$2923,2,0) -> 67.17
A32: 30 | B32: Blok A | C32: 4-do'kon | D32: Alimov Ulugbek Rustamovich | E32: 30809640040022 | F32: 951773373 | G32: PREMIUM PRIME SERVICE" MAS`ULIYATI CHEKLANGAN JAMIYATI | H32: 0 | I32: 1 | J32: 15 | K32: Toxirov Davron Xaydar O'g'li | L32: 32404910600036 | M32: Toxirov Davron Xaydar O'g'li | N32: +998331019999 | O32: 32404910600036 | Q32: 4 | R32: QAMBAROV AZIZJON AKMAL O‘G‘LI G‘ULOMOV XASAN G‘OFURJON O‘G‘LI MUXAMEDOV SHAXZOD UKTAMOVICH ABDURAXIMOV ASADBEK ABDURAZZOQ O‘G‘LI | S32: 53007046750058 31511840290024 31708880070039 50402056620022 | T32: 0998977401500 998909323640 998998008383 998974230204 | U32: YTT | V32: AOS | W32: LG420211622505 | X32: Faol | Y32: =VLOOKUP(L32,'[2]йил бошидан'!$B$5:$C$2923,2,0) -> 0.03
A33: 31 | B33: Blok A | C33: 4-do'kon | D33: Alimov Ulugbek Rustamovich | E33: 30809640040022 | F33: 951773373 | G33: PREMIUM PRIME SERVICE" MAS`ULIYATI CHEKLANGAN JAMIYATI | H33: 0 | I33: 1 | J33: 15 | K33: Tojiboyev Abbosjon Umidjon O'g'li | L33: 50304026520049 | M33: Tojiboyev Abbosjon Umidjon O'g'li | N33: +998998151711 | O33: 50304026520049 | Q33: 1 | R33: RAXIMOV OYBEK ULUG‘BEK O‘G‘LI | S33: 52106036610026 | T33: 998900156240 | U33: YTT | V33: AOS | W33: VG298430010687 | X33: Faol | Y33: =VLOOKUP(L33,'[2]йил бошидан'!$B$5:$C$2923,2,0) -> 1.52
A34: 32 | B34: Blok A | C34: 4-do'kon | D34: Alimov Ulugbek Rustamovich | E34: 30809640040022 | F34: 951773373 | G34: PREMIUM PRIME SERVICE" MAS`ULIYATI CHEKLANGAN JAMIYATI | H34: 0 | I34: 1 | J34: 15 | K34: AXMADALIYEV ABU-BAKIR ALISHER O‘G‘LI | L34: 50610006610047 | M34: AXMADALIYEV ABU-BAKIR ALISHER O‘G‘LI | N34: 940555514 | O34: 50610006610047 | Q34: 1 | R34: AXMADALIYEV ABU-BAKIR ALISHER O‘G‘LI | S34: 50610006610047 | T34: 940555514 | U34: YTT | V34: AOS | X34: Faol | Y34: 0
A35: 33 | B35: Blok A | C35: 4-do'kon | D35: Alimov Ulugbek Rustamovich | E35: 30809640040022 | F35: 951773373 | G35: PREMIUM PRIME SERVICE" MAS`ULIYATI CHEKLANGAN JAMIYATI | H35: 0 | I35: 1 | J35: 15 | K35: Tursunov Dilnur Dilshod O'g'li | L35: 50905066620030 | M35: Tursunov Dilnur Dilshod O'g'li | N35: +998940704343 | O35: 50905066620030 | Q35: 3 | R35: OBIDJONOV MUXAMMADALI OMILJON O‘G‘LI NARMAMATOV SHUXRATJON MAMADALIYEVICH ALIYEV MAHMUDJON IBROHIM O‘G‘LI | S35: 53105086540052 31512892940037 32704985970035 | T35: 998908287654 998909433118 998977100023 | U35: YTT | V35: AOS | W35: LG420211622506 | X35: Faol | Y35: =VLOOKUP(L35,'[2]йил бошидан'!$B$5:$C$2923,2,0) -> 0.01
A36: 34 | B36: Blok A | C36: 4-do'kon | D36: Alimov Ulugbek Rustamovich | E36: 30809640040022 | F36: 951773373 | G36: PREMIUM PRIME SERVICE" MAS`ULIYATI CHEKLANGAN JAMIYATI | H36: 0 | I36: 1 | J36: 15 | K36: Sobirjonov Shukurjon Sharifjon O'g'li | L36: 52107006610066 | M36: Sobirjonov Shukurjon Sharifjon O'g'li | N36: 903208696 | O36: 52107006610066 | Q36: 1 | R36: Sobirjonov Shukurjon Sharifjon O'g'li | S36: 52107006610066 | T36: 903208696 | U36: YTT | V36: AOS | X36: Faol | Y36: 0
A37: 35 | B37: Blok A | C37: 5-do'kon | D37: Alimov Ulugbek Rustamovich | E37: 30809640040022 | F37: 951773373 | G37: PREMIUM PRIME SERVICE" MAS`ULIYATI CHEKLANGAN JAMIYATI | H37: 180 | I37: 1 | J37: 20 | K37: Igamberdiyev Umarjon Mamurjon O'g'li | L37: 50610036610017 | M37: Igamberdiyev Umarjon Mamurjon O'g'li | N37: 959054505 | O37: 50610036610017 | Q37: 1 | R37: Igamberdiyev Umarjon Mamurjon O'g'li | S37: 50610036610017 | T37: 959054505 | U37: YTT | V37: QQS | W37: LG420211621216 | X37: Faol | Y37: 0
A38: 36 | B38: Blok A | C38: 5-do'kon | D38: Alimov Ulugbek Rustamovich | E38: 30809640040022 | F38: 951773373 | G38: PREMIUM PRIME SERVICE" MAS`ULIYATI CHEKLANGAN JAMIYATI | H38: 0 | I38: 1 | J38: 20 | K38: Ataxanov Nodirbek Nozimovich | L38: 32412820770019 | M38: Ataxanov Nodirbek Nozimovich | N38: +998983671982 | O38: 32412820770019 | Q38: 5 | R38: Abdullaxatov Xusan Abduzabixilla O‘g‘li Raximjonov Shaxzod Baxrom O‘g‘li Ubaydullaev Lutfulla Sayfullaevich Tadjibaev Muxammad Muxtorovich Tolipov Abror Avzal O‘g‘li | S38: 50511046600033 50603046610016 31001820222272 31009854320041 30511910211112 | T38: 332022233 946753634 977734473 932704944 977005005 | U38: YTT | V38: AOS | W38: UZ201125124435 | X38: Faol | Y38: 0
A39: 37 | B39: Blok A | C39: 5-do'kon | D39: Alimov Ulugbek Rustamovich | E39: 30809640040022 | F39: 951773373 | G39: PREMIUM PRIME SERVICE" MAS`ULIYATI CHEKLANGAN JAMIYATI | H39: 0 | I39: 1 | J39: 20 | K39: "Pc Planet" Mchj | L39: 51903016670013 | M39: Qudratillayev Raxmatilla Xikmatilla O'g'li | N39: 971570705 | P39: 311717825 | Q39: 6 | R39: Qudratillayev Raxmatilla Xikmatilla Ogli Alimuxamedov Gulomjan Nasirdjanovich Vaxobov Xikmatilla Nosirjanova Mastura Alimuxamedov Shokirjon Sultangulov Rais Ayratovich | S39: 51903016670013 30707860210039 31406740720019 62405076540021 31601820210011 30610907340029 | T39: 971570705 881708000 935000705 909050008 977710002 884759000 | U39: Yuridik | V39: AOS | W39: LG420211621179 | X39: Faol
A40: 38 | B40: Blok A | C40: 5-do'kon | D40: Alimov Ulugbek Rustamovich | E40: 30809640040022 | F40: 951773373 | G40: PREMIUM PRIME SERVICE" MAS`ULIYATI CHEKLANGAN JAMIYATI | H40: 0 | I40: 1 | J40: 20 | K40: Ergashev Komiljon Rustam O'g'li | L40: 31511996570010 | M40: Ergashev Komiljon Rustam O'g'li | N40: +998978784911 | O40: 31511996570010 | Q40: 5 | R40: G‘ANIJONOV SHOHRUHBEK NOMOZBEK O‘G‘LI SHERZODOV ABDULLOX DILMUROD O‘G‘LI ALIMOV ISLOMBEK XASANOVICH SOBIROV SHARIFJON ABROR O‘G‘LI SHOKIROV RAVSHANJON SHAVKATJON O‘G‘LI | S40: 30709951910060 51710006610058 51805076610018 30901996610114 31008961360021 | T40: 998978784911 | U40: YTT | V40: AOS | W40: LG420211621148 | X40: Faol | Y40: =VLOOKUP(L40,'[2]йил бошидан'!$B$5:$C$2923,2,0) -> 0.05
A41: 39 | B41: Blok A | C41: 5-do'kon | D41: Alimov Ulugbek Rustamovich | E41: 30809640040022 | F41: 951773373 | G41: PREMIUM PRIME SERVICE" MAS`ULIYATI CHEKLANGAN JAMIYATI | H41: 0 | I41: 1 | J41: 20 | K41: Yusupov Ibrohim G‘Ofur O'g'li | L41: 32602950210141 | M41: Yusupov Ibrohim G‘Ofur O'g'li | N41: +998940810818 | O41: 32602950210141 | Q41: 3 | R41: TOLIPOV ABROR AVZAL O‘G‘LI RASULMUXAMEDOV DILSHOD SHERZOD O‘G‘LI ABDUNABIYEV RAVSHAN RUSTAM O‘G‘LI | S41: 30511910211112 50308056530018 51602076590043 | T41: 998940810818 | U41: YTT | V41: AOS | W41: LG420211621171 | X41: Faol | Y41: 0
...
